Workbook

Sheet 2024年12月29日
A1: 用电负荷(MW) | B1: 外送计划(MW) | C1: 火电总计划(MW) | D1: 新能源总计划(MW) | E1: 用户侧价格(元/MWh) | F1: 特高压雁淮直流外送-电力(MW) | G1: 塔山3# | H1: 塔山4# | I1: 王家岭电厂1#机 | J1: 王家岭电厂2#机 | K1: 神泉1# | L1: 神泉2# | M1: 神泉二期3号机 | N1: 神泉二期4号机 | O1: 紫荆电厂01# | P1: 紫荆电厂02# | Q1: 系统负荷实际值(MW) | R1: 外送实际值(MW) | S1: 风电实际值(MW) | T1: 光伏实际值(MW) | U1: 风光总加实际值(MW) | V1: 水电实际值(MW) | W1: 频率实际值(MW) | X1: 实际上旋备用(MW) | Y1: 实际下旋备用(MW) | Z1: 非市场化机组实际出力(MW) | AA1: 是否越限 | AB1: 湖关三-潮流(MW) | AC1: 实时节点边际电价-电能量价格(元/MWh) | AD1: 实时节点边际电价-阻塞价格(元/MWh) | AE1: 实时节点边际电价-节点电价(元/MWh) | AF1: 日前节点边际电价-电能量价格(元/MWh) | AG1: 日前节点边际电价-阻塞价格(元/MWh) | AH1: 日前节点边际电价-节点电价(元/MWh) | AI1: 日前联络线电力值(MW) | AJ1: 省内负荷预测电力值(MW) | AK1: 总加电力值(MW) | AL1: 电力值(MW) | AM1: 风电(MW) | AN1: 光伏(MW) | AO1: 实时出清价格(元/MWh) | AP1: 日前出清价格(元/MWh) | AQ1: 日前-出清概况 | AR1: 实时-出清概况 | AS1: 1#日前结果(MW) | AT1: 1#实时结果(MW) | AU1: 1#日前价格(元/MWh) | AV1: 1#实时价格(元/MWh) | AW1: 2#日前结果(MW) | AX1: 2#实时结果(MW) | AY1: 2#日前价格(元/MWh) | AZ1: 2#实时价格(元/MWh)
A2: 34109.37 | B2: -6653.73 | C2: 29697.37 | D2: 12727.88 | E2: 250 | F2: 7199 | G2: 0 | H2: 363.37 | I2: 579.91 | J2: 636.69 | K2: 279.24 | L2: 279.7 | M2: 735.48 | N2: 733.42 | O2: 360.7 | P2: 301.4 | Q2: 34114.35 | R2: 6673.244 | S2: 12183.918 | T2: 0.897 | U2: 12184.815 | V2: 177.26 | W2: 50.03 | X2: 12806.14 | Y2: 3821.637 | Z2: 1266.11 | AA2: 是 | AB2: -4466.313 | AC2: 250 | AD2: 0 | AE2: 250 | AF2: 0 | AG2: 0 | AH2: 0 | AI2: 6692 | AJ2: 34027 | AK2: 40719 | AL2: 13331.42 | AM2: 13331.42 | AN2: 0 | AO2: 250 | AP2: 0 | AQ2: 12月29日,直调用电预测最大负荷3981.70万千瓦，最小3108.41万千瓦；外送电最大857.90万千瓦，最小584.55万千瓦；日前现货市场出清节点电价最大272.22元/MWh，最小0.00元/MWh，算术平均68.65元/MWh；日前现货市场火电机组运行126台，运行机组容量44292.00MW；日前调频市场需求最大值4580.50MW，需求最小值为4071.90MW；中标机组最多24台，中标机组最少22台；中标机组调频性能指标平均值为3.96；边际出清价格最大29.99元/MWh，最小13.00元/MWh；火电机组必开102台次、必开容量32631.00MW，必停23台次、必停容量3093.00MW。 | AR2: 12月29日直调用电实际最大负荷3825.44万千瓦，最小2989.70万千瓦；12月29日日外送电实际安排最大857.90万千瓦，最小584.55万千瓦；12月29日实时现货市场出清价格最大272.22元/MWh，最小0.00元/MWh，算术平均81.63元/MWh；实时现货市场有阻塞，卧湖三回断面负载率最高，达到100.00%;湖关三回线断面负载率次高，达到100.00%。 | AS2: 360.55 | AT2: 361 | AU2: 0 | AV2: 250 | AW2: 300.55 | AX2: 301 | AY2: 0 | AZ2: 250
A3: 34202.94 | B3: -6608 | C3: 29955.81 | D3: 12494.65 | E3: 250 | F3: 7185 | G3: 0 | H3: 447.1 | I3: 581.81 | J3: 642.16 | K3: 269.7 | L3: 271.79 | M3: 735.07 | N3: 737.12 | O3: 360.9 | P3: 302.6 | Q3: 34199.04 | R3: 6657.937 | S3: 12141.311 | T3: 0.928 | U3: 12142.239 | V3: 177.51 | W3: 50.033 | X3: 12697.16 | Y3: 4024.523 | Z3: 1277 | AA3: 是 | AB3: -4452.166 | AC3: 250 | AD3: 0 | AE3: 250 | AF3: 240 | AG3: 0 | AH3: 240 | AI3: 6692 | AJ3: 33762.4 | AK3: 40454.4 | AL3: 13337.66 | AM3: 13337.66 | AN3: 0 | AO3: 250 | AP3: 240 | AS3: 361 | AT3: 361 | AU3: 240 | AV3: 250 | AW3: 301 | AX3: 301 | AY3: 240 | AZ3: 250
A4: 34008.42 | B4: -6574.4 | C4: 29968.04 | D4: 12307.14 | E4: 250 | F4: 7185 | G4: 0 | H4: 447.97 | I4: 584.27 | J4: 642.03 | K4: 272.72 | L4: 271.79 | M4: 703.82 | N4: 696.01 | O4: 361.5 | P4: 304.3 | Q4: 34151.25 | R4: 6403.009 | S4: 12136.723 | T4: 1.081 | U4: 12137.804 | V4: 176 | W4: 50.028 | X4: 13006.76 | Y4: 3743.441 | Z4: 1277.66 | AA4: 是 | AB4: -4514.64 | AC4: 250 | AD4: 0 | AE4: 250 | AF4: 250 | AG4: 0 | AH4: 250 | AI4: 6692 | AJ4: 33684 | AK4: 40376 | AL4: 13329.92 | AM4: 13329.92 | AN4: 0 | AO4: 250 | AP4: 250 | AS4: 361 | AT4: 361 | AU4: 250 | AV4: 250 | AW4: 301 | AX4: 301 | AY4: 250 | AZ4: 250
A5: 33689.55 | B5: -6608 | C5: 30132.38 | D5: 12194.75 | E5: 250 | F5: 7197 | G5: 0 | H5: 448.82 | I5: 584.73 | J5: 643.41 | K5: 271.33 | L5: 273.19 | M5: 704.24 | N5: 705.06 | O5: 363 | P5: 303.6 | Q5: 33543.69 | R5: 6673.011 | S5: 12096.301 | T5: 0.931 | U5: 12097.232 | V5: 176.95 | W5: 50.013 | X5: 13442.32 | Y5: 3660.734 | Z5: 1266 | AA5: 是 | AB5: -4497.41 | AC5: 250 | AD5: 0 | AE5: 250 | AF5: 249 | AG5: 0 | AH5: 249 | AI5: 6692 | AJ5: 33607.6 | AK5: 40299.6 | AL5: 13316.76 | AM5: 13316.76 | AN5: 0 | AO5: 250 | AP5: 249 | AS5: 361 | AT5: 361 | AU5: 249 | AV5: 250 | AW5: 301 | AX5: 301 | AY5: 249 | AZ5: 250
A6: 33500.24 | B6: -6511.47 | C6: 30151.55 | D6: 12045.3 | E6: 250 | F6: 7197 | G6: 0 | H6: 448.82 | I6: 585.02 | J6: 646.38 | K6: 271.33 | L6: 273.65 | M6: 704.24 | N6: 705.47 | O6: 362.6 | P6: 304.1 | Q6: 33497.12 | R6: 6555.705 | S6: 12003.343 | T6: 0.863 | U6: 12004.206 | V6: 177.51 | W6: 50.013 | X6: 13638.55 | Y6: 3480.488 | Z6: 1254.57 | AA6: 是 | AB6: -4511.978 | AC6: 250 | AD6: 0 | AE6: 250 | AF6: 250 | AG6: 0 | AH6: 250 | AI6: 6692 | AJ6: 33232.8 | AK6: 39924.8 | AL6: 13323.14 | AM6: 13323.14 | AN6: 0 | AO6: 250 | AP6: 250 | AS6: 361 | AT6: 361 | AU6: 250 | AV6: 250 | AW6: 301 | AX6: 301 | AY6: 250 | AZ6: 250
A7: 33302.93 | B7: -6628 | C7: 29963.04 | D7: 12064.5 | E7: 249 | F7: 7199 | G7: 0 | H7: 411.21 | I7: 584.66 | J7: 638.8 | K7: 271.1 | L7: 272.72 | M7: 700.95 | N7: 700.54 | O7: 359.8 | P7: 300.6 | Q7: 33287.88 | R7: 6776.266 | S7: 12027.315 | T7: 0.879 | U7: 12028.194 | V7: 178.15 | W7: 49.99 | X7: 13639.31 | Y7: 3429.443 | Z7: 1245.74 | AA7: 是 | AB7: -4511.978 | AC7: 249 | AD7: 0 | AE7: 249 | AF7: 171 | AG7: 76.67 | AH7: 247.67 | AI7: 6692 | AJ7: 33109 | AK7: 39801 | AL7: 13341.58 | AM7: 13341.58 | AN7: 0 | AO7: 249 | AP7: 176.6 | AS7: 361 | AT7: 361 | AU7: 247.67 | AV7: 249 | AW7: 301 | AX7: 301 | AY7: 247.67 | AZ7: 249
A8: 33252.81 | B8: -6628 | C8: 29887.11 | D8: 12086.59 | E8: 249 | F8: 7199 | G8: 0 | H8: 393.26 | I8: 584.39 | J8: 635.69 | K8: 272.26 | L8: 273.65 | M8: 700.12 | N8: 700.54 | O8: 361.8 | P8: 304.3 | Q8: 32959.48 | R8: 6773.553 | S8: 12158.98 | T8: 0.893 | U8: 12159.874 | V8: 178.26 | W8: 49.975 | X8: 14012.12 | Y8: 3092.652 | Z8: 1254.41 | AA8: 是 | AB8: -4506.515 | AC8: 249 | AD8: 0 | AE8: 249 | AF8: 200 | AG8: 44.45 | AH8: 244.45 | AI8: 6692 | AJ8: 32761.2 | AK8: 39453.2 | AL8: 13377.67 | AM8: 13377.67 | AN8: 0 | AO8: 249 | AP8: 203.23 | AS8: 361 | AT8: 361 | AU8: 244.45 | AV8: 249 | AW8: 301 | AX8: 301 | AY8: 244.45 | AZ8: 249
A9: 33039.65 | B9: -6628 | C9: 29738.04 | D9: 12021.79 | E9: 249 | F9: 7197 | G9: 0 | H9: 360.81 | I9: 584.27 | J9: 636.89 | K9: 271.33 | L9: 272.72 | M9: 698.89 | N9: 700.95 | O9: 362.2 | P9: 304 | Q9: 32884.05 | R9: 6687.864 | S9: 12126.34 | T9: 0.884 | U9: 12127.224 | V9: 177.81 | W9: 49.968 | X9: 13542.59 | Y9: 2928.578 | Z9: 1248.54 | AA9: 是 | AB9: -4527.946 | AC9: 249 | AD9: 0 | AE9: 249 | AF9: 231 | AG9: 10 | AH9: 241 | AI9: 6692 | AJ9: 32738 | AK9: 39430 | AL9: 13424.14 | AM9: 13424.14 | AN9: 0 | AO9: 249 | AP9: 231.73 | AS9: 361 | AT9: 361 | AU9: 241 | AV9: 249 | AW9: 301 | AX9: 301 | AY9: 241 | AZ9: 249
A10: 32725.13 | B10: -6608 | C10: 29365.92 | D10: 12056.52 | E10: 249 | F10: 7200 | G10: 0 | H10: 279.62 | I10: 580.28 | J10: 636.56 | K10: 270.86 | L10: 272.26 | M10: 700.12 | N10: 700.95 | O10: 359.1 | P10: 302 | Q10: 32895.91 | R10: 6467.971 | S10: 12259.468 | T10: 0.89 | U10: 12260.358 | V10: -134.04 | W10: 50.031 | X10: 13585.05 | Y10: 3156.58 | Z10: 1247.45 | AA10: 是 | AB10: -4522.343 | AC10: 249 | AD10: 0 | AE10: 249 | AF10: 249 | AG10: 0 | AH10: 249 | AI10: 6692 | AJ10: 32740.7 | AK10: 39432.7 | AL10: 13508.65 | AM10: 13508.65 | AN10: 0 | AO10: 249 | AP10: 249 | AS10: 361 | AT10: 361 | AU10: 249 | AV10: 249 | AW10: 301 | AX10: 301 | AY10: 249 | AZ10: 249
A11: 32746.98 | B11: -6610.15 | C11: 30177.94 | D11: 12152.92 | E11: 260 | F11: 7200 | G11: 0 | H11: 398.39 | I11: 579.47 | J11: 635.33 | K11: 340.64 | L11: 340.64 | M11: 745.35 | N11: 754.39 | O11: 369.1 | P11: 310.2 | Q11: 32970.09 | R11: 6638.375 | S11: 12506.24 | T11: 0.882 | U11: 12507.122 | V11: -731.34 | W11: 49.966 | X11: 12996.53 | Y11: 3736.055 | Z11: 1243.95 | AA11: 是 | AB11: -4274.689 | AC11: 260 | AD11: 0 | AE11: 260 | AF11: 240 | AG11: 0 | AH11: 240 | AI11: 6692 | AJ11: 32634.5 | AK11: 39326.5 | AL11: 13620.61 | AM11: 13620.61 | AN11: 0 | AO11: 260 | AP11: 240 | AS11: 361 | AT11: 363.14 | AU11: 240 | AV11: 260 | AW11: 301 | AX11: 304.24 | AY11: 240 | AZ11: 260
A12: 32582.62 | B12: -6610.15 | C12: 30331.6 | D12: 12247.72 | E12: 255 | F12: 7200 | G12: 0 | H12: 450.54 | I12: 580.09 | J12: 649.92 | K12: 290.63 | L12: 296.22 | M12: 749.87 | N12: 748.64 | O12: 363.4 | P12: 305 | Q12: 32919.52 | R12: 6545.756 | S12: 12694.703 | T12: 0.88 | U12: 12695.584 | V12: -1029.59 | W12: 49.983 | X12: 12331.53 | Y12: 3799.574 | Z12: 1247.25 | AA12: 是 | AB12: -4480.181 | AC12: 255 | AD12: 0 | AE12: 255 | AF12: 249 | AG12: 0 | AH12: 249 | AI12: 6692 | AJ12: 32442 | AK12: 39134 | AL12: 13736.91 | AM12: 13736.91 | AN12: 0 | AO12: 255 | AP12: 249 | AS12: 361 | AT12: 361 | AU12: 249 | AV12: 255 | AW12: 301 | AX12: 301 | AY12: 249 | AZ12: 255
A13: 32614.91 | B13: -6610.15 | C13: 30413.62 | D13: 12383.2 | E13: 255 | F13: 7200 | G13: 0 | H13: 447.1 | I13: 584.23 | J13: 646.95 | K13: 278.54 | L13: 279.7 | M13: 749.46 | N13: 748.64 | O13: 362.6 | P13: 303.9 | Q13: 32620.53 | R13: 6662.87 | S13: 12997.188 | T13: 0.878 | U13: 12998.066 | V13: -1023.39 | W13: 49.967 | X13: 12810.16 | Y13: 3332.342 | Z13: 1273.87 | AA13: 是 | AB13: -4500.071 | AC13: 255 | AD13: 0 | AE13: 255 | AF13: 249 | AG13: 0 | AH13: 249 | AI13: 6692 | AJ13: 32313.7 | AK13: 39005.7 | AL13: 13861.1 | AM13: 13861.1 | AN13: 0 | AO13: 255 | AP13: 249 | AS13: 361 | AT13: 361 | AU13: 249 | AV13: 255 | AW13: 301 | AX13: 301 | AY13: 249 | AZ13: 255
A14: 32814.57 | B14: -6628 | C14: 30744.21 | D14: 12481.81 | E14: 260 | F14: 7200 | G14: 0 | H14: 448.82 | I14: 584.47 | J14: 646.53 | K14: 346.69 | L14: 341.57 | M14: 762.61 | N14: 763.44 | O14: 394.6 | P14: 352.8 | Q14: 32500.64 | R14: 6797.055 | S14: 13413.987 | T14: 0.88 | U14: 13414.867 | V14: -1021.04 | W14: 49.997 | X14: 13558.35 | Y14: 3136.326 | Z14: 1297.75 | AA14: 是 | AB14: -4257.601 | AC14: 260 | AD14: 0 | AE14: 260 | AF14: 200 | AG14: 44.45 | AH14: 244.45 | AI14: 6692 | AJ14: 32251.8 | AK14: 38943.8 | AL14: 14038.33 | AM14: 14038.33 | AN14: 0 | AO14: 260 | AP14: 203.29 | AS14: 361 | AT14: 393.81 | AU14: 244.45 | AV14: 260 | AW14: 301 | AX14: 352.35 | AY14: 244.45 | AZ14: 260
... A97: 32432.55 | B97: -6775.55 | C97: 26737.63 | D97: 14501.87 | E97: 19.13 | F97: 7197 | G97: 0 | H97: 200.15 | I97: 282.29 | J97: 302.71 | K97: 271.33 | L97: 272.49 | M97: 636.4 | N97: 634.76 | O97: 356.5 | P97: 306.2 | Q97: 32364.84 | R97: 6765.648 | S97: 16894.418 | T97: 0.979 | U97: 16895.398 | V97: -1145.99 | W97: 50.006 | X97: 16965.63 | Y97: 1041.859 | Z97: 1188.03 | AA97: 是 | AB97: -4804.036 | AC97: 0 | AD97: 266.67 | AE97: 266.67 | AF97: 0 | AG97: 266.67 | AH97: 266.67 | AI97: 6594 | AJ97: 33437.9 | AK97: 40031.9 | AL97: 17804.14 | AM97: 17804.14 | AN97: 0 | AO97: 19.13 | AP97: 18.22 | AS97: 361 | AT97: 361 | AU97: 266.67 | AV97: 266.67 | AW97: 301 | AX97: 301 | AY97: 266.67 | AZ97: 266.67

Sheet 2024年12月28日
A1: 用电负荷(MW) | B1: 外送计划(MW) | C1: 火电总计划(MW) | D1: 新能源总计划(MW) | E1: 用户侧价格(元/MWh) | F1: 特高压雁淮直流外送-电力(MW) | G1: 塔山3# | H1: 塔山4# | I1: 王家岭电厂1#机 | J1: 王家岭电厂2#机 | K1: 神泉1# | L1: 神泉2# | M1: 神泉二期3号机 | N1: 神泉二期4号机 | O1: 紫荆电厂01# | P1: 紫荆电厂02# | Q1: 系统负荷实际值(MW) | R1: 外送实际值(MW) | S1: 风电实际值(MW) | T1: 光伏实际值(MW) | U1: 风光总加实际值(MW) | V1: 水电实际值(MW) | W1: 频率实际值(MW) | X1: 实际上旋备用(MW) | Y1: 实际下旋备用(MW) | Z1: 非市场化机组实际出力(MW) | AA1: 是否越限 | AB1: 湖关三-潮流(MW) | AC1: 实时节点边际电价-电能量价格(元/MWh) | AD1: 实时节点边际电价-阻塞价格(元/MWh) | AE1: 实时节点边际电价-节点电价(元/MWh) | AF1: 日前节点边际电价-电能量价格(元/MWh) | AG1: 日前节点边际电价-阻塞价格(元/MWh) | AH1: 日前节点边际电价-节点电价(元/MWh) | AI1: 日前联络线电力值(MW) | AJ1: 省内负荷预测电力值(MW) | AK1: 总加电力值(MW) | AL1: 电力值(MW) | AM1: 风电(MW) | AN1: 光伏(MW) | AO1: 实时出清价格(元/MWh) | AP1: 日前出清价格(元/MWh) | AQ1: 日前-出清概况 | AR1: 实时-出清概况 | AS1: 1#日前结果(MW) | AT1: 1#实时结果(MW) | AU1: 1#日前价格(元/MWh) | AV1: 1#实时价格(元/MWh) | AW1: 2#日前结果(MW) | AX1: 2#实时结果(MW) | AY1: 2#日前价格(元/MWh) | AZ1: 2#实时价格(元/MWh)
A2: 34064.23 | B2: -7878.73 | C2: 26890.26 | D2: 15253.8 | E2: 18.23 | F2: 7199 | G2: 0 | H2: 196.74 | I2: 301.03 | J2: 300.04 | K2: 271.1 | L2: 272.26 | M2: 638.05 | N2: 637.22 | O2: 360.4 | P2: 304.8 | Q2: 34248.14 | R2: 8038.111 | S2: 16826.362 | T2: -0.025 | U2: 16826.337 | V2: 253.65 | W2: 49.99 | X2: 15196.99 | Y2: 2282.629 | Z2: 1141.82 | AA2: 是 | AB2: -4775.18 | AC2: 0 | AD2: 266.67 | AE2: 266.67 | AF2: 100 | AG2: 155.56 | AH2: 255.56 | AI2: 6692 | AJ2: 34807.2 | AK2: 41499.2 | AL2: 17376.35 | AM2: 17376.35 | AN2: 0 | AO2: 18.23 | AP2: 110.43 | AQ2: 12月28日,直调用电预测最大负荷4080.09万千瓦，最小3212.23万千瓦；外送电最大898.60万千瓦，最小585.75万千瓦；日前现货市场出清节点电价最大368.00元/MWh，最小0.00元/MWh，算术平均148.08元/MWh；日前现货市场火电机组运行127台，运行机组容量44892.00MW；日前调频市场需求最大值4678.89MW，需求最小值为4166.59MW；中标机组最多26台，中标机组最少23台；中标机组调频性能指标平均值为4.15；边际出清价格最大29.98元/MWh，最小13.99元/MWh；火电机组必开102台次、必开容量32631.00MW，必停23台次、必停容量3093.00MW。 | AR2: 12月28日直调用电实际最大负荷3905.31万千瓦，最小2915.28万千瓦；12月28日日外送电实际安排最大898.60万千瓦，最小585.75万千瓦；12月28日实时现货市场出清价格最大336.00元/MWh，最小0.00元/MWh，算术平均114.15元/MWh；实时现货市场有阻塞，卧湖三回断面负载率最高，达到100.00%;湖关三回线断面负载率次高，达到100.00%。 | AS2: 361 | AT2: 361 | AU2: 255.56 | AV2: 266.67 | AW2: 301 | AX2: 301 | AY2: 255.56 | AZ2: 266.67
A3: 34228.77 | B3: -7945.66 | C3: 27020.65 | D3: 16495.26 | E3: 17.99 | F3: 7199 | G3: 0 | H3: 195.02 | I3: 301.8 | J3: 298.4 | K3: 271.79 | L3: 272.26 | M3: 637.64 | N3: 637.22 | O3: 364 | P3: 304.5 | Q3: 34274.69 | R3: 7885.751 | S3: 16504.254 | T3: -0.037 | U3: 16504.217 | V3: 254.15 | W3: 50.022 | X3: 15037.59 | Y3: 2353.488 | Z3: 1131.85 | AA3: 是 | AB3: -4766.495 | AC3: 0 | AD3: 266.67 | AE3: 266.67 | AF3: 0 | AG3: 266.67 | AH3: 266.67 | AI3: 6692 | AJ3: 34973.9 | AK3: 41665.9 | AL3: 17339.28 | AM3: 17339.28 | AN3: 0 | AO3: 17.99 | AP3: 17.93 | AS3: 361 | AT3: 361 | AU3: 266.67 | AV3: 266.67 | AW3: 301 | AX3: 301 | AY3: 266.67 | AZ3: 266.67
A4: 34049.72 | B4: -7811.98 | C4: 27142.88 | D4: 16007.6 | E4: 18.07 | F4: 7199 | G4: 0 | H4: 195.89 | I4: 300.94 | J4: 301.77 | K4: 272.49 | L4: 271.79 | M4: 638.05 | N4: 637.64 | O4: 362.4 | P4: 305.5 | Q4: 34165.88 | R4: 7791.876 | S4: 16351.664 | T4: -0.011 | U4: 16351.653 | V4: 298.2 | W4: 50.016 | X4: 15059.46 | Y4: 2285.391 | Z4: 1306.81 | AA4: 是 | AB4: -4776.721 | AC4: 0 | AD4: 266.67 | AE4: 266.67 | AF4: 0 | AG4: 266.67 | AH4: 266.67 | AI4: 6692 | AJ4: 34441.5 | AK4: 41133.5 | AL4: 17287.1 | AM4: 17287.1 | AN4: 0 | AO4: 18.07 | AP4: 18.04 | AS4: 361 | AT4: 361 | AU4: 266.67 | AV4: 266.67 | AW4: 301 | AX4: 301 | AY4: 266.67 | AZ4: 266.67
A5: 33793.49 | B5: -7816.68 | C5: 27238.21 | D5: 15773.91 | E5: 18.1 | F5: 7199 | G5: 0 | H5: 196.74 | I5: 301.39 | J5: 300.21 | K5: 272.26 | L5: 273.19 | M5: 638.05 | N5: 638.05 | O5: 363.7 | P5: 305.1 | Q5: 33607.95 | R5: 7947.314 | S5: 16293.353 | T5: -0.101 | U5: 16293.252 | V5: 296.05 | W5: 49.991 | X5: 15584.26 | Y5: 1757.918 | Z5: 1288.88 | AA5: 是 | AB5: -4763.414 | AC5: 0 | AD5: 266.67 | AE5: 266.67 | AF5: 240 | AG5: 0 | AH5: 240 | AI5: 6692 | AJ5: 34422.7 | AK5: 41114.7 | AL5: 17238.97 | AM5: 17238.97 | AN5: 0 | AO5: 18.1 | AP5: 240 | AS5: 361 | AT5: 361 | AU5: 240 | AV5: 266.67 | AW5: 301 | AX5: 301 | AY5: 240 | AZ5: 266.67
A6: 33486.27 | B6: -7828.26 | C6: 27230.59 | D6: 15436.57 | E6: 18.19 | F6: 7199 | G6: 0 | H6: 196.74 | I6: 301.2 | J6: 299.6 | K6: 271.1 | L6: 272.26 | M6: 637.22 | N6: 637.22 | O6: 362.5 | P6: 304.4 | Q6: 33405.96 | R6: 7809.719 | S6: 16163.827 | T6: -0.123 | U6: 16163.704 | V6: 296.7 | W6: 50.027 | X6: 15791.93 | Y6: 1586.113 | Z6: 1330.64 | AA6: 是 | AB6: -4755.009 | AC6: 0 | AD6: 266.67 | AE6: 266.67 | AF6: 0 | AG6: 266.67 | AH6: 266.67 | AI6: 6692 | AJ6: 34253.7 | AK6: 40945.7 | AL6: 17211.09 | AM6: 17211.09 | AN6: 0 | AO6: 18.19 | AP6: 18.12 | AS6: 361 | AT6: 361 | AU6: 266.67 | AV6: 266.67 | AW6: 301 | AX6: 301 | AY6: 266.67 | AZ6: 266.67
A7: 33066.63 | B7: -7515.98 | C7: 27199.75 | D7: 14703.38 | E7: 18.38 | F7: 7199 | G7: 0 | H7: 195.89 | I7: 301.26 | J7: 299.23 | K7: 271.33 | L7: 272.26 | M7: 637.64 | N7: 637.22 | O7: 364 | P7: 305.9 | Q7: 33085.11 | R7: 7656.835 | S7: 16308.523 | T7: -0.092 | U7: 16308.431 | V7: 298 | W7: 49.969 | X7: 16365.43 | Y7: 1119.633 | Z7: 1331.92 | AA7: 是 | AB7: -4735.398 | AC7: 0 | AD7: 266.67 | AE7: 266.67 | AF7: 0 | AG7: 266.67 | AH7: 266.67 | AI7: 6692 | AJ7: 33968.1 | AK7: 40660.1 | AL7: 17173.97 | AM7: 17173.97 | AN7: 0 | AO7: 18.38 | AP7: 18.11 | AS7: 361 | AT7: 361 | AU7: 266.67 | AV7: 266.67 | AW7: 301 | AX7: 301 | AY7: 266.67 | AZ7: 266.67
A8: 33073.48 | B8: -7473.89 | C8: 27310.15 | D8: 14657.04 | E8: 18.43 | F8: 7197 | G8: 0 | H8: 195.02 | I8: 301.34 | J8: 299.11 | K8: 272.26 | L8: 273.19 | M8: 637.64 | N8: 637.64 | O8: 358.3 | P8: 304.9 | Q8: 33244.4 | R8: 7399.964 | S8: 16204.022 | T8: -0.073 | U8: 16203.95 | V8: 297.5 | W8: 49.986 | X8: 16357.21 | Y8: 1214.23 | Z8: 1345.22 | AA8: 是 | AB8: -4773.219 | AC8: 0 | AD8: 266.67 | AE8: 266.67 | AF8: 0 | AG8: 266.67 | AH8: 266.67 | AI8: 6692 | AJ8: 34110 | AK8: 40802 | AL8: 17142.58 | AM8: 17142.58 | AN8: 0 | AO8: 18.43 | AP8: 18.03 | AS8: 361 | AT8: 361 | AU8: 266.67 | AV8: 266.67 | AW8: 301 | AX8: 301 | AY8: 266.67 | AZ8: 266.67
A9: 32929.25 | B9: -7460.34 | C9: 27348.07 | D9: 14709.9 | E9: 18.56 | F9: 7199 | G9: 0 | H9: 195.02 | I9: 301.13 | J9: 299.88 | K9: 271.1 | L9: 272.49 | M9: 637.22 | N9: 637.22 | O9: 356.7 | P9: 303.3 | Q9: 32904.58 | R9: 7639.481 | S9: 16203.24 | T9: -0.083 | U9: 16203.157 | V9: 297.35 | W9: 50.034 | X9: 16551.21 | Y9: 1080.059 | Z9: 1352.39 | AA9: 是 | AB9: -4782.604 | AC9: 0 | AD9: 266.67 | AE9: 266.67 | AF9: 0 | AG9: 266.67 | AH9: 266.67 | AI9: 6692 | AJ9: 33680.5 | AK9: 40372.5 | AL9: 17109.54 | AM9: 17109.54 | AN9: 0 | AO9: 18.56 | AP9: 18.28 | AS9: 361 | AT9: 361 | AU9: 266.67 | AV9: 266.67 | AW9: 301 | AX9: 301 | AY9: 266.67 | AZ9: 266.67
A10: 32911.8 | B10: -7463.74 | C10: 27505.17 | D10: 14725.69 | E10: 18.59 | F10: 7199 | G10: 0 | H10: 194.17 | I10: 301.06 | J10: 300.03 | K10: 271.33 | L10: 272.49 | M10: 637.22 | N10: 638.05 | O10: 357.3 | P10: 302.8 | Q10: 32840.99 | R10: 7390.044 | S10: 16181.046 | T10: -0.013 | U10: 16181.033 | V10: -314.3 | W10: 50.031 | X10: 16325.89 | Y10: 1245.566 | Z10: 1344.53 | AA10: 是 | AB10: -4746.185 | AC10: 0 | AD10: 266.67 | AE10: 266.67 | AF10: 0 | AG10: 266.67 | AH10: 266.67 | AI10: 6692 | AJ10: 33676.2 | AK10: 40368.2 | AL10: 17077.58 | AM10: 17077.58 | AN10: 0 | AO10: 18.59 | AP10: 18.39 | AS10: 361 | AT10: 361 | AU10: 266.67 | AV10: 266.67 | AW10: 301 | AX10: 301 | AY10: 266.67 | AZ10: 266.67
A11: 32723.73 | B11: -7440.65 | C11: 27538.72 | D11: 14511.82 | E11: 18.62 | F11: 7199 | G11: 0 | H11: 195.02 | I11: 301.28 | J11: 300.89 | K11: 272.26 | L11: 272.49 | M11: 637.64 | N11: 637.64 | O11: 360.5 | P11: 304.2 | Q11: 32883.33 | R11: 7549.896 | S11: 16117.167 | T11: 0.002 | U11: 16117.169 | V11: -313 | W11: 49.965 | X11: 16034.36 | Y11: 1477.398 | Z11: 1347.27 | AA11: 是 | AB11: -4741.562 | AC11: 0 | AD11: 266.67 | AE11: 266.67 | AF11: 250 | AG11: 0 | AH11: 250 | AI11: 6692 | AJ11: 33603 | AK11: 40295 | AL11: 17051.37 | AM11: 17051.37 | AN11: 0 | AO11: 18.62 | AP11: 250 | AS11: 361 | AT11: 361 | AU11: 250 | AV11: 266.67 | AW11: 301 | AX11: 301 | AY11: 250 | AZ11: 266.67
A12: 32614 | B12: -7412.37 | C12: 27539.42 | D12: 15000.02 | E12: 18.87 | F12: 7199 | G12: 0 | H12: 194.17 | I12: 301.23 | J12: 300.06 | K12: 271.33 | L12: 272.72 | M12: 638.05 | N12: 637.64 | O12: 360.3 | P12: 305.2 | Q12: 32746.44 | R12: 7204.006 | S12: 15917.513 | T12: -0.035 | U12: 15917.478 | V12: -919.65 | W12: 50.034 | X12: 15835.83 | Y12: 1469.168 | Z12: 1340.34 | AA12: 是 | AB12: -4701.92 | AC12: 0 | AD12: 266.67 | AE12: 266.67 | AF12: 240 | AG12: 0 | AH12: 240 | AI12: 6692 | AJ12: 33469.7 | AK12: 40161.7 | AL12: 17031.67 | AM12: 17031.67 | AN12: 0 | AO12: 18.87 | AP12: 240 | AS12: 361 | AT12: 361 | AU12: 240 | AV12: 266.67 | AW12: 301 | AX12: 301 | AY12: 240 | AZ12: 266.67
A13: 32648.31 | B13: -7409.55 | C13: 27947.13 | D13: 15007.42 | E13: 18.84 | F13: 7199 | G13: 0 | H13: 195.02 | I13: 301.08 | J13: 300.27 | K13: 271.1 | L13: 273.65 | M13: 637.64 | N13: 637.64 | O13: 358.6 | P13: 306.2 | Q13: 32642.91 | R13: 7436.68 | S13: 15870.652 | T13: -0.012 | U13: 15870.64 | V13: -921.5 | W13: 50.029 | X13: 15651.05 | Y13: 1625.844 | Z13: 1355.15 | AA13: 是 | AB13: -4676.287 | AC13: 0 | AD13: 266.67 | AE13: 266.67 | AF13: 250 | AG13: 0 | AH13: 250 | AI13: 6692 | AJ13: 33399.1 | AK13: 40091.1 | AL13: 17015.83 | AM13: 17015.83 | AN13: 0 | AO13: 18.84 | AP13: 250 | AS13: 361 | AT13: 361 | AU13: 250 | AV13: 266.67 | AW13: 301 | AX13: 301 | AY13: 250 | AZ13: 266.67
A14: 32586.93 | B14: -7399.03 | C14: 27503.83 | D14: 15543.07 | E14: 19.08 | F14: 7199 | G14: 0 | H14: 195.02 | I14: 301.05 | J14: 300.54 | K14: 271.1 | L14: 272.26 | M14: 637.64 | N14: 637.22 | O14: 362.4 | P14: 300.4 | Q14: 32544.32 | R14: 7549.4 | S14: 15760.008 | T14: 0.019 | U14: 15760.026 | V14: -906.19 | W14: 49.968 | X14: 15537.74 | Y14: 1740.898 | Z14: 1353.68 | AA14: 是 | AB14: -4670.264 | AC14: 0 | AD14: 266.67 | AE14: 266.67 | AF14: 250 | AG14: 0 | AH14: 250 | AI14: 6692 | AJ14: 33404.9 | AK14: 40096.9 | AL14: 16998.26 | AM14: 16998.26 | AN14: 0 | AO14: 19.08 | AP14: 250 | AS14: 361 | AT14: 361 | AU14: 250 | AV14: 266.67 | AW14: 301 | AX14: 301 | AY14: 250 | AZ14: 266.67
... A97: 33649.35 | B97: -6363.38 | C97: 29008.1 | D97: 12814.59 | E97: 258 | F97: 7199 | G97: 0 | H97: 247.16 | I97: 499.95 | J97: 556.33 | K97: 340.41 | L97: 340.41 | M97: 746.99 | N97: 749.46 | O97: 356.3 | P97: 298.7 | Q97: 33620.7 | R97: 6349.743 | S97: 12271.47 | T97: 0.843 | U97: 12272.313 | V97: 176.26 | W97: 50.037 | X97: 14070.05 | Y97: 2999.965 | Z97: 1255.37 | AA97: 是 | AB97: -4330.58 | AC97: 258 | AD97: 0 | AE97: 258 | AF97: 260 | AG97: 0 | AH97: 260 | AI97: 6594 | AJ97: 34553.4 | AK97: 41147.4 | AL97: 13326.84 | AM97: 13326.84 | AN97: 0 | AO97: 258 | AP97: 260 | AS97: 361 | AT97: 361 | AU97: 260 | AV97: 258 | AW97: 301 | AX97: 301 | AY97: 260 | AZ97: 258

Sheet 2024年12月27日
A1: 用电负荷(MW) | B1: 外送计划(MW) | C1: 火电总计划(MW) | D1: 新能源总计划(MW) | E1: 用户侧价格(元/MWh) | F1: 特高压雁淮直流外送-电力(MW) | G1: 塔山3# | H1: 塔山4# | I1: 王家岭电厂1#机 | J1: 王家岭电厂2#机 | K1: 神泉1# | L1: 神泉2# | M1: 神泉二期3号机 | N1: 神泉二期4号机 | O1: 紫荆电厂01# | P1: 紫荆电厂02# | Q1: 系统负荷实际值(MW) | R1: 外送实际值(MW) | S1: 风电实际值(MW) | T1: 光伏实际值(MW) | U1: 风光总加实际值(MW) | V1: 水电实际值(MW) | W1: 频率实际值(MW) | X1: 实际上旋备用(MW) | Y1: 实际下旋备用(MW) | Z1: 非市场化机组实际出力(MW) | AA1: 是否越限 | AB1: 湖关三-潮流(MW) | AC1: 实时节点边际电价-电能量价格(元/MWh) | AD1: 实时节点边际电价-阻塞价格(元/MWh) | AE1: 实时节点边际电价-节点电价(元/MWh) | AF1: 日前节点边际电价-电能量价格(元/MWh) | AG1: 日前节点边际电价-阻塞价格(元/MWh) | AH1: 日前节点边际电价-节点电价(元/MWh) | AI1: 日前联络线电力值(MW) | AJ1: 省内负荷预测电力值(MW) | AK1: 总加电力值(MW) | AL1: 电力值(MW) | AM1: 风电(MW) | AN1: 光伏(MW) | AO1: 实时出清价格(元/MWh) | AP1: 日前出清价格(元/MWh) | AQ1: 日前-出清概况 | AR1: 实时-出清概况 | AS1: 1#日前结果(MW) | AT1: 1#实时结果(MW) | AU1: 1#日前价格(元/MWh) | AV1: 1#实时价格(元/MWh) | AW1: 2#日前结果(MW) | AX1: 2#实时结果(MW) | AY1: 2#日前价格(元/MWh) | AZ1: 2#实时价格(元/MWh)
A2: 33569.4 | B2: -6923.28 | C2: 29045.1 | D2: 12907.81 | E2: 250 | F2: 7199 | G2: 0 | H2: 200.15 | I2: 422.13 | J2: 496.61 | K2: 371.58 | L2: 372.28 | M2: 763.44 | N2: 763.85 | O2: 359 | P2: 305.7 | Q2: 33629.22 | R2: 6777.863 | S2: 13698.675 | T2: 1.079 | U2: 13699.754 | V2: 66.3 | W2: 49.985 | X2: 14273.03 | Y2: 3557.855 | Z2: 1121.02 | AA2: 是 | AB2: -4359.996 | AC2: 250 | AD2: 0 | AE2: 250 | AF2: 249 | AG2: 0 | AH2: 249 | AI2: 6692 | AJ2: 34600 | AK2: 41292 | AL2: 15905.29 | AM2: 15905.29 | AN2: 0 | AO2: 250 | AP2: 249 | AQ2: 12月27日,直调用电预测最大负荷4044.70万千瓦，最小3152.68万千瓦；外送电最大898.50万千瓦，最小585.75万千瓦；日前现货市场出清节点电价最大270.00元/MWh，最小0.00元/MWh，算术平均88.74元/MWh；日前现货市场火电机组运行126台，运行机组容量44542.00MW；日前调频市场需求最大值4643.50MW，需求最小值为4180.60MW；中标机组最多25台，中标机组最少22台；中标机组调频性能指标平均值为4.43；边际出清价格最大21.50元/MWh，最小14.01元/MWh；火电机组必开96台次、必开容量30091.00MW，必停23台次、必停容量3093.00MW。 | AR2: 12月27日直调用电实际最大负荷3888.24万千瓦，最小2940.72万千瓦；12月27日日外送电实际安排最大898.50万千瓦，最小585.75万千瓦；12月27日实时现货市场出清价格最大268.00元/MWh，最小0.00元/MWh，算术平均40.87元/MWh；实时现货市场有阻塞，铺吉双断面负载率最高，达到100.00%;湖关三回线断面负载率次高，达到100.00%。 | AS2: 361 | AT2: 361 | AU2: 249 | AV2: 250 | AW2: 301 | AX2: 301 | AY2: 249 | AZ2: 250
A3: 33515.97 | B3: -7107.28 | C3: 27782.3 | D3: 13258.51 | E3: 65.06 | F3: 7199 | G3: 0 | H3: 194.17 | I3: 345.82 | J3: 394.52 | K3: 302.5 | L3: 304.36 | M3: 688.61 | N3: 688.61 | O3: 358.7 | P3: 304.7 | Q3: 33575.34 | R3: 7121.826 | S3: 14005.654 | T3: 1.229 | U3: 14006.883 | V3: 64.65 | W3: 50.019 | X3: 14290.08 | Y3: 3566.062 | Z3: 1120.68 | AA3: 是 | AB3: -4637.206 | AC3: 50 | AD3: 211.11 | AE3: 261.11 | AF3: 50 | AG3: 211.11 | AH3: 261.11 | AI3: 6692 | AJ3: 34587 | AK3: 41279 | AL3: 16043.05 | AM3: 16043.05 | AN3: 0 | AO3: 65.06 | AP3: 64.42 | AS3: 361 | AT3: 361 | AU3: 261.11 | AV3: 261.11 | AW3: 301 | AX3: 301 | AY3: 261.11 | AZ3: 261.11
A4: 33418.64 | B4: -7083.92 | C4: 27546.85 | D4: 13706.56 | E4: 157 | F4: 7199 | G4: 0 | H4: 195.02 | I4: 302.33 | J4: 330.12 | K4: 273.65 | L4: 273.19 | M4: 634.76 | N4: 637.64 | O4: 360 | P4: 297.5 | Q4: 33205.96 | R4: 7312.708 | S4: 14292.957 | T4: 1.092 | U4: 14294.049 | V4: 66.89 | W4: 49.967 | X4: 14754.34 | Y4: 3090.324 | Z4: 1117.88 | AA4: 是 | AB4: -4814.821 | AC4: 149.9 | AD4: 100.11 | AE4: 250.01 | AF4: 100 | AG4: 155.56 | AH4: 255.56 | AI4: 6692 | AJ4: 34321 | AK4: 41013 | AL4: 16145.91 | AM4: 16145.91 | AN4: 0 | AO4: 157 | AP4: 110.61 | AS4: 361 | AT4: 361 | AU4: 255.56 | AV4: 250.01 | AW4: 301 | AX4: 301 | AY4: 255.56 | AZ4: 250.01
A5: 33217.93 | B5: -7135.31 | C5: 27445.38 | D5: 14037.4 | E5: 110.99 | F5: 7199 | G5: 0 | H5: 194.17 | I5: 302.27 | J5: 332.16 | K5: 273.19 | L5: 273.19 | M5: 635.58 | N5: 635.58 | O5: 358.8 | P5: 304.4 | Q5: 32965.51 | R5: 7169.473 | S5: 14620.631 | T5: 1.109 | U5: 14621.74 | V5: 67.49 | W5: 50.004 | X5: 15459.98 | Y5: 2386.188 | Z5: 1118.52 | AA5: 是 | AB5: -4817.062 | AC5: 100 | AD5: 155.56 | AE5: 255.56 | AF5: 0.1 | AG5: 266.56 | AH5: 266.66 | AI5: 6692 | AJ5: 34081 | AK5: 40773 | AL5: 16253.97 | AM5: 16253.97 | AN5: 0 | AO5: 110.99 | AP5: 18.35 | AS5: 361 | AT5: 361 | AU5: 266.66 | AV5: 255.56 | AW5: 301 | AX5: 301 | AY5: 266.66 | AZ5: 255.56
A6: 32824.88 | B6: -7177.49 | C6: 26995.87 | D6: 14206.32 | E6: 19.02 | F6: 7199 | G6: 0 | H6: 195.89 | I6: 300.73 | J6: 331.49 | K6: 273.19 | L6: 271.79 | M6: 636.4 | N6: 635.99 | O6: 364.2 | P6: 304.8 | Q6: 32836.35 | R6: 7218.658 | S6: 15140.839 | T6: 1.191 | U6: 15142.029 | V6: 66.85 | W6: 50.033 | X6: 16068.79 | Y6: 1996.621 | Z6: 1128.73 | AA6: 是 | AB6: -4811.88 | AC6: 0 | AD6: 266.67 | AE6: 266.67 | AF6: 0 | AG6: 266.67 | AH6: 266.67 | AI6: 6692 | AJ6: 33908 | AK6: 40600 | AL6: 16356.22 | AM6: 16356.22 | AN6: 0 | AO6: 19.02 | AP6: 18.35 | AS6: 361 | AT6: 361 | AU6: 266.67 | AV6: 266.67 | AW6: 301 | AX6: 301 | AY6: 266.67 | AZ6: 266.67
A7: 32599.85 | B7: -7188.57 | C7: 26778.95 | D7: 14208.66 | E7: 19.06 | F7: 7199 | G7: 0 | H7: 195.89 | I7: 298.71 | J7: 329.19 | K7: 273.19 | L7: 272.72 | M7: 635.99 | N7: 636.4 | O7: 363.6 | P7: 303.6 | Q7: 32722.61 | R7: 7210.028 | S7: 15361.383 | T7: 1.149 | U7: 15362.533 | V7: 67.1 | W7: 50.033 | X7: 16413.17 | Y7: 1888.773 | Z7: 1124.41 | AA7: 是 | AB7: -4818.323 | AC7: 0 | AD7: 266.67 | AE7: 266.67 | AF7: 0 | AG7: 266.67 | AH7: 266.67 | AI7: 6692 | AJ7: 33786 | AK7: 40478 | AL7: 16448.62 | AM7: 16448.62 | AN7: 0 | AO7: 19.06 | AP7: 18.41 | AS7: 361 | AT7: 361 | AU7: 266.67 | AV7: 266.67 | AW7: 301 | AX7: 301 | AY7: 266.67 | AZ7: 266.67
A8: 32607.71 | B8: -7190.95 | C8: 26768.42 | D8: 14071.1 | E8: 19.01 | F8: 7199 | G8: 0 | H8: 195.02 | I8: 300.26 | J8: 329.69 | K8: 272.72 | L8: 272.72 | M8: 637.22 | N8: 635.58 | O8: 366.8 | P8: 304.2 | Q8: 32397.52 | R8: 7221.461 | S8: 15587.645 | T8: 1.12 | U8: 15588.765 | V8: 170.8 | W8: 49.968 | X8: 16956.83 | Y8: 1272.691 | Z8: 1121.87 | AA8: 是 | AB8: -4804.876 | AC8: 0 | AD8: 266.67 | AE8: 266.67 | AF8: 0 | AG8: 266.67 | AH8: 266.67 | AI8: 6692 | AJ8: 33605 | AK8: 40297 | AL8: 16514.24 | AM8: 16514.24 | AN8: 0 | AO8: 19.01 | AP8: 18.41 | AS8: 361 | AT8: 361 | AU8: 266.67 | AV8: 266.67 | AW8: 301 | AX8: 301 | AY8: 266.67 | AZ8: 266.67
A9: 32300.31 | B9: -7173.46 | C9: 26777.06 | D9: 13965.79 | E9: 18.95 | F9: 7199 | G9: 0 | H9: 195.89 | I9: 300.8 | J9: 330.81 | K9: 273.65 | L9: 273.19 | M9: 635.99 | N9: 635.58 | O9: 364.9 | P9: 306.1 | Q9: 32453.62 | R9: 7109.719 | S9: 15676.645 | T9: 1.212 | U9: 15677.857 | V9: -137.56 | W9: 49.969 | X9: 16801.62 | Y9: 1610.461 | Z9: 1129.56 | AA9: 是 | AB9: -4811.04 | AC9: 0 | AD9: 266.67 | AE9: 266.67 | AF9: 0 | AG9: 266.67 | AH9: 266.67 | AI9: 6692 | AJ9: 33442 | AK9: 40134 | AL9: 16572.91 | AM9: 16572.91 | AN9: 0 | AO9: 18.95 | AP9: 18.53 | AS9: 361 | AT9: 361 | AU9: 266.67 | AV9: 266.67 | AW9: 301 | AX9: 301 | AY9: 266.67 | AZ9: 266.67
A10: 32381.07 | B10: -7088.87 | C10: 26775.16 | D10: 13623.69 | E10: 18.93 | F10: 7199 | G10: 0 | H10: 195.02 | I10: 300.32 | J10: 330.88 | K10: 273.65 | L10: 272.49 | M10: 636.81 | N10: 635.58 | O10: 365.2 | P10: 304.7 | Q10: 32142.56 | R10: 7232.82 | S10: 15577.773 | T10: 1.126 | U10: 15578.899 | V10: -443.6 | W10: 49.997 | X10: 16575.49 | Y10: 1746.258 | Z10: 1244.48 | AA10: 是 | AB10: -4811.88 | AC10: 0 | AD10: 266.67 | AE10: 266.67 | AF10: 100 | AG10: 155.56 | AH10: 255.56 | AI10: 6692 | AJ10: 33376 | AK10: 40068 | AL10: 16619.77 | AM10: 16619.77 | AN10: 0 | AO10: 18.93 | AP10: 110.81 | AS10: 361 | AT10: 361 | AU10: 255.56 | AV10: 266.67 | AW10: 301 | AX10: 301 | AY10: 255.56 | AZ10: 266.67
A11: 32308.29 | B11: -6929.54 | C11: 26775.3 | D11: 14436.11 | E11: 18.88 | F11: 7199 | G11: 0 | H11: 194.17 | I11: 300.61 | J11: 330.1 | K11: 273.19 | L11: 273.19 | M11: 634.76 | N11: 634.76 | O11: 364.4 | P11: 305.2 | Q11: 32275.3 | R11: 6852.757 | S11: 15639.069 | T11: 1.139 | U11: 15640.208 | V11: -750.35 | W11: 49.976 | X11: 16585.23 | Y11: 1733.988 | Z11: 1236.51 | AA11: 是 | AB11: -4810.899 | AC11: 0 | AD11: 266.67 | AE11: 266.67 | AF11: 200 | AG11: 44.44 | AH11: 244.44 | AI11: 6692 | AJ11: 33294 | AK11: 39986 | AL11: 16683.34 | AM11: 16683.34 | AN11: 0 | AO11: 18.88 | AP11: 203.08 | AS11: 361 | AT11: 361 | AU11: 244.44 | AV11: 266.67 | AW11: 301 | AX11: 301 | AY11: 244.44 | AZ11: 266.67
A12: 32024.13 | B12: -7133.14 | C12: 26776.61 | D12: 14498.9 | E12: 19.02 | F12: 7199 | G12: 0 | H12: 194.17 | I12: 299.98 | J12: 330.39 | K12: 273.89 | L12: 273.19 | M12: 636.4 | N12: 635.99 | O12: 365.1 | P12: 304.8 | Q12: 32110.62 | R12: 7160.376 | S12: 15773.976 | T12: 1.172 | U12: 15775.147 | V12: -1055.06 | W12: 50.018 | X12: 16273.49 | Y12: 1751.699 | Z12: 1229.74 | AA12: 是 | AB12: -4816.082 | AC12: 0 | AD12: 266.67 | AE12: 266.67 | AF12: 0.1 | AG12: 266.56 | AH12: 266.66 | AI12: 6692 | AJ12: 33204 | AK12: 39896 | AL12: 16742.25 | AM12: 16742.25 | AN12: 0 | AO12: 19.02 | AP12: 18.95 | AS12: 361 | AT12: 361 | AU12: 266.66 | AV12: 266.67 | AW12: 301 | AX12: 301 | AY12: 266.66 | AZ12: 266.67
A13: 31990.7 | B13: -6990.54 | C13: 26775.68 | D13: 15118.36 | E13: 19.06 | F13: 7199 | G13: 0 | H13: 195.02 | I13: 300.05 | J13: 330.74 | K13: 273.19 | L13: 271.79 | M13: 636.4 | N13: 635.99 | O13: 365.3 | P13: 303 | Q13: 31891.17 | R13: 7050.549 | S13: 16137.58 | T13: 1.101 | U13: 16138.681 | V13: -1046.56 | W13: 49.972 | X13: 16976.52 | Y13: 1054.668 | Z13: 1225.07 | AA13: 是 | AB13: -4811.18 | AC13: 0 | AD13: 266.67 | AE13: 266.67 | AF13: 200 | AG13: 44.44 | AH13: 244.44 | AI13: 6692 | AJ13: 33141 | AK13: 39833 | AL13: 16793.71 | AM13: 16793.71 | AN13: 0 | AO13: 19.06 | AP13: 203.11 | AS13: 361 | AT13: 361 | AU13: 244.44 | AV13: 266.67 | AW13: 301 | AX13: 301 | AY13: 244.44 | AZ13: 266.67
A14: 31897.6 | B14: -6976.54 | C14: 26775.33 | D14: 15364.75 | E14: 19.17 | F14: 7199 | G14: 0 | H14: 195.02 | I14: 300.99 | J14: 330.4 | K14: 273.19 | L14: 273.19 | M14: 636.4 | N14: 634.76 | O14: 364.7 | P14: 304.1 | Q14: 31881.65 | R14: 6990.449 | S14: 16199.764 | T14: 1.14 | U14: 16200.904 | V14: -1047.06 | W14: 50.022 | X14: 17105.57 | Y14: 1020.039 | Z14: 1231.62 | AA14: 是 | AB14: -4807.818 | AC14: 0 | AD14: 266.67 | AE14: 266.67 | AF14: 200 | AG14: 44.44 | AH14: 244.44 | AI14: 6692 | AJ14: 33065 | AK14: 39757 | AL14: 16829.8 | AM14: 16829.8 | AN14: 0 | AO14: 19.17 | AP14: 203.1 | AS14: 361 | AT14: 361 | AU14: 244.44 | AV14: 266.67 | AW14: 301 | AX14: 301 | AY14: 244.44 | AZ14: 266.67
... A97: 33687.71 | B97: -7020.2 | C97: 26256.3 | D97: 14742.58 | E97: 18.71 | F97: 7199 | G97: 0 | H97: 195.02 | I97: 301.72 | J97: 330.7 | K97: 272.26 | L97: 273.65 | M97: 637.22 | N97: 638.05 | O97: 357.9 | P97: 301.2 | Q97: 33699.97 | R97: 6476.739 | S97: 16797.771 | T97: 0.004 | U97: 16797.775 | V97: 73.55 | W97: 50.026 | X97: 17580.17 | Y97: 1004.367 | Z97: 1156.06 | AA97: 是 | AB97: -4744.363 | AC97: 0 | AD97: 266.67 | AE97: 266.67 | AF97: 0 | AG97: 266.67 | AH97: 266.67 | AI97: 6594 | AJ97: 34018 | AK97: 40612 | AL97: 16701.55 | AM97: 16701.55 | AN97: 0 | AO97: 18.71 | AP97: 18.4 | AS97: 361 | AT97: 361 | AU97: 266.67 | AV97: 266.67 | AW97: 301 | AX97: 301 | AY97: 266.67 | AZ97: 266.67

Sheet 2024年12月26日
A1: 用电负荷(MW) | B1: 外送计划(MW) | C1: 火电总计划(MW) | D1: 新能源总计划(MW) | E1: 用户侧价格(元/MWh) | F1: 特高压雁淮直流外送-电力(MW) | G1: 塔山3# | H1: 塔山4# | I1: 王家岭电厂1#机 | J1: 王家岭电厂2#机 | K1: 神泉1# | L1: 神泉2# | M1: 神泉二期3号机 | N1: 神泉二期4号机 | O1: 紫荆电厂01# | P1: 紫荆电厂02# | Q1: 系统负荷实际值(MW) | R1: 外送实际值(MW) | S1: 风电实际值(MW) | T1: 光伏实际值(MW) | U1: 风光总加实际值(MW) | V1: 水电实际值(MW) | W1: 频率实际值(MW) | X1: 实际上旋备用(MW) | Y1: 实际下旋备用(MW) | Z1: 非市场化机组实际出力(MW) | AA1: 是否越限 | AB1: 湖关三-潮流(MW) | AC1: 实时节点边际电价-电能量价格(元/MWh) | AD1: 实时节点边际电价-阻塞价格(元/MWh) | AE1: 实时节点边际电价-节点电价(元/MWh) | AF1: 日前节点边际电价-电能量价格(元/MWh) | AG1: 日前节点边际电价-阻塞价格(元/MWh) | AH1: 日前节点边际电价-节点电价(元/MWh) | AI1: 日前联络线电力值(MW) | AJ1: 省内负荷预测电力值(MW) | AK1: 总加电力值(MW) | AL1: 电力值(MW) | AM1: 风电(MW) | AN1: 光伏(MW) | AO1: 实时出清价格(元/MWh) | AP1: 日前出清价格(元/MWh) | AQ1: 日前-出清概况 | AR1: 实时-出清概况 | AS1: 1#日前结果(MW) | AT1: 1#实时结果(MW) | AU1: 1#日前价格(元/MWh) | AV1: 1#实时价格(元/MWh) | AW1: 2#日前结果(MW) | AX1: 2#实时结果(MW) | AY1: 2#日前价格(元/MWh) | AZ1: 2#实时价格(元/MWh)
A2: 34117.9 | B2: -5970.8 | C2: 33827.92 | D2: 9339.27 | E2: 320 | F2: 7199 | G2: 547.08 | H2: 550.49 | I2: 504.47 | J2: 608.73 | K2: 440.89 | L2: 441.13 | M2: 899.1 | N2: 918.01 | O2: 464.3 | P2: 455.5 | Q2: 34241.77 | R2: 6033.034 | S2: 8551.082 | T2: 1.095 | U2: 8552.176 | V2: 50.31 | W2: 50.033 | X2: 10863.83 | Y2: 8879.795 | Z2: 1112.25 | AA2: 是 | AB2: -3583.136 | AC2: 320 | AD2: 0 | AE2: 320 | AF2: 310 | AG2: 0 | AH2: 310 | AI2: 6692 | AJ2: 34594.8 | AK2: 41286.8 | AL2: 11250.25 | AM2: 11250.25 | AN2: 0 | AO2: 320 | AP2: 310 | AQ2: 12月26日,直调用电预测最大负荷4048.73万千瓦，最小3233.33万千瓦；外送电最大898.60万千瓦，最小585.75万千瓦；日前现货市场出清节点电价最大370.00元/MWh，最小0.00元/MWh，算术平均239.33元/MWh；日前现货市场火电机组运行129台，运行机组容量46122.00MW；日前调频市场需求最大值4647.53MW，需求最小值为4180.39MW；中标机组最多25台，中标机组最少21台；中标机组调频性能指标平均值为4.26；边际出清价格最大26.00元/MWh，最小5.00元/MWh；火电机组必开96台次、必开容量30091.00MW，必停23台次、必停容量3093.00MW。 | AR2: 12月26日直调用电实际最大负荷3890.94万千瓦，最小2961.62万千瓦；12月26日日外送电实际安排最大898.60万千瓦，最小585.75万千瓦；12月26日实时现货市场出清价格最大396.00元/MWh，最小0.00元/MWh，算术平均235.18元/MWh；实时现货市场有阻塞，湖关三回线断面负载率最高，达到100.00%;临会双＋榆久双断面负载率次高，达到89.00%。 | AS2: 468 | AT2: 468 | AU2: 310 | AV2: 320 | AW2: 468 | AX2: 468 | AY2: 310 | AZ2: 320
A3: 34112.97 | B3: -5796.8 | C3: 34937.41 | D3: 9140.93 | E3: 329 | F3: 7199 | G3: 549.64 | H3: 550.49 | I3: 575.69 | J3: 625.98 | K3: 515.79 | L3: 516.26 | M3: 899.92 | N3: 919.25 | O3: 466.2 | P3: 463.5 | Q3: 34287.06 | R3: 6048.873 | S3: 8220.997 | T3: 1.12 | U3: 8222.117 | V3: 50.3 | W3: 49.989 | X3: 10475.48 | Y3: 8648.744 | Z3: 1118.78 | AA3: 是 | AB3: -3440.539 | AC3: 329 | AD3: 0 | AE3: 329 | AF3: 300 | AG3: 0 | AH3: 300 | AI3: 6692 | AJ3: 34597.9 | AK3: 41289.9 | AL3: 11118.99 | AM3: 11118.99 | AN3: 0 | AO3: 329 | AP3: 300 | AS3: 393.27 | AT3: 468 | AU3: 300 | AV3: 329 | AW3: 369 | AX3: 468 | AY3: 300 | AZ3: 329
A4: 34168.43 | B4: -5158.12 | C4: 35050.1 | D4: 8994.39 | E4: 325 | F4: 7199 | G4: 549.64 | H4: 552.21 | I4: 582.55 | J4: 624.86 | K4: 555.1 | L4: 567.89 | M4: 899.1 | N4: 920.07 | O4: 466 | P4: 463.5 | Q4: 33944.46 | R4: 5151.796 | S4: 7821.325 | T4: 1.07 | U4: 7822.395 | V4: 50.35 | W4: 49.992 | X4: 11320.84 | Y4: 6801.123 | Z4: 1124.86 | AA4: 是 | AB4: -3333.241 | AC4: 325 | AD4: 0 | AE4: 325 | AF4: 304 | AG4: 0 | AH4: 304 | AI4: 6692 | AJ4: 34205.6 | AK4: 40897.6 | AL4: 10967.64 | AM4: 10967.64 | AN4: 0 | AO4: 325 | AP4: 304 | AS4: 468 | AT4: 468 | AU4: 304 | AV4: 325 | AW4: 468 | AX4: 468 | AY4: 304 | AZ4: 325
A5: 33898.61 | B5: -4714.04 | C5: 32796.47 | D5: 8793.07 | E5: 282.2 | F5: 7199 | G5: 448.82 | H5: 449.66 | I5: 581.97 | J5: 628.28 | K5: 551.84 | L5: 554.87 | M5: 898.69 | N5: 919.25 | O5: 379.7 | P5: 376.6 | Q5: 33853.25 | R5: 4594.406 | S5: 7499.49 | T5: 1.079 | U5: 7500.569 | V5: 50.35 | W5: 49.979 | X5: 11641.87 | Y5: 6478.363 | Z5: 1137.87 | AA5: 是 | AB5: -3516.74 | AC5: 282.2 | AD5: 0 | AE5: 282.2 | AF5: 300 | AG5: 0 | AH5: 300 | AI5: 6692 | AJ5: 34164.5 | AK5: 40856.5 | AL5: 10832.15 | AM5: 10832.15 | AN5: 0 | AO5: 282.2 | AP5: 300 | AS5: 450.88 | AT5: 369 | AU5: 300 | AV5: 282.2 | AW5: 441.28 | AX5: 369 | AY5: 300 | AZ5: 282.2
A6: 33566.56 | B6: -4686.9 | C6: 32615.09 | D6: 8541.55 | E6: 290 | F6: 7199 | G6: 353.12 | H6: 354.81 | I6: 581.03 | J6: 626.28 | K6: 554.4 | L6: 557.89 | M6: 899.51 | N6: 920.48 | O6: 355.1 | P6: 299.9 | Q6: 33685.74 | R6: 4665.53 | S6: 7234.531 | T6: 1.074 | U6: 7235.605 | V6: 173.35 | W6: 50.031 | X6: 11481.63 | Y6: 6537.709 | Z6: 1136.14 | AA6: 是 | AB6: -3613.673 | AC6: 290 | AD6: 0 | AE6: 290 | AF6: 300 | AG6: 0 | AH6: 300 | AI6: 6692 | AJ6: 33900.4 | AK6: 40592.4 | AL6: 10705.42 | AM6: 10705.42 | AN6: 0 | AO6: 290 | AP6: 300 | AS6: 432.36 | AT6: 361 | AU6: 300 | AV6: 290 | AW6: 412.89 | AX6: 301 | AY6: 300 | AZ6: 290
A7: 33497.92 | B7: -4754.16 | C7: 33518.61 | D7: 8248.39 | E7: 306 | F7: 7199 | G7: 449.66 | H7: 447.97 | I7: 580.25 | J7: 626.55 | K7: 557.43 | L7: 569.29 | M7: 894.58 | N7: 920.07 | O7: 453.6 | P7: 398.9 | Q7: 33421.5 | R7: 4851.1 | S7: 7135.519 | T7: 1.079 | U7: 7136.598 | V7: 173.3 | W7: 49.972 | X7: 11467.12 | Y7: 6534.496 | Z7: 1123.46 | AA7: 是 | AB7: -3422.889 | AC7: 306 | AD7: 0 | AE7: 306 | AF7: 300 | AG7: 0 | AH7: 300 | AI7: 6692 | AJ7: 33824.4 | AK7: 40516.4 | AL7: 10586.93 | AM7: 10586.93 | AN7: 0 | AO7: 306 | AP7: 300 | AS7: 388.82 | AT7: 460 | AU7: 300 | AV7: 306 | AW7: 344.42 | AX7: 400 | AY7: 300 | AZ7: 306
A8: 33285.56 | B8: -4740.58 | C8: 33491.42 | D8: 7957.47 | E8: 301 | F8: 7199 | G8: 449.66 | H8: 447.97 | I8: 580.11 | J8: 627.31 | K8: 570.92 | L8: 573.48 | M8: 893.76 | N8: 918.84 | O8: 470.4 | P8: 445.5 | Q8: 33297.23 | R8: 4770.171 | S8: 7272.787 | T8: 1.008 | U8: 7273.795 | V8: 173.35 | W8: 50.03 | X8: 11803.87 | Y8: 6202.258 | Z8: 1248.65 | AA8: 是 | AB8: -3340.104 | AC8: 301 | AD8: 0 | AE8: 301 | AF8: 300 | AG8: 0 | AH8: 300 | AI8: 6692 | AJ8: 33692.6 | AK8: 40384.6 | AL8: 10475.17 | AM8: 10475.17 | AN8: 0 | AO8: 301 | AP8: 300 | AS8: 385.61 | AT8: 468 | AU8: 300 | AV8: 301 | AW8: 353.72 | AX8: 447.6 | AY8: 300 | AZ8: 301
A9: 33197.1 | B9: -4623.4 | C9: 33632.06 | D9: 7713.37 | E9: 308 | F9: 7199 | G9: 448.82 | H9: 448.82 | I9: 579.41 | J9: 626.97 | K9: 567.89 | L9: 572.54 | M9: 898.69 | N9: 919.25 | O9: 470 | P9: 465.9 | Q9: 33250.11 | R9: 4621.484 | S9: 7620.405 | T9: 1.025 | U9: 7621.43 | V9: 163.45 | W9: 50.035 | X9: 12355.81 | Y9: 5665.328 | Z9: 1253.6 | AA9: 是 | AB9: -3316.712 | AC9: 308 | AD9: 0 | AE9: 308 | AF9: 300 | AG9: 0 | AH9: 300 | AI9: 6692 | AJ9: 33423.4 | AK9: 40115.4 | AL9: 10373.72 | AM9: 10373.72 | AN9: 0 | AO9: 308 | AP9: 300 | AS9: 467.71 | AT9: 468 | AU9: 300 | AV9: 308 | AW9: 452.72 | AX9: 468 | AY9: 300 | AZ9: 308
A10: 33147.24 | B10: -4362.6 | C10: 33135.28 | D10: 7503.15 | E10: 300 | F10: 7199 | G10: 449.66 | H10: 450.54 | I10: 580.61 | J10: 627.47 | K10: 570.92 | L10: 572.78 | M10: 900.34 | N10: 920.07 | O10: 429 | P10: 403.4 | Q10: 33104.06 | R10: 4329.915 | S10: 7930.695 | T10: 1.091 | U10: 7931.786 | V10: -245.55 | W10: 50.016 | X10: 12798.18 | Y10: 5289.617 | Z10: 1255.08 | AA10: 是 | AB10: -2888.5 | AC10: 300 | AD10: 0 | AE10: 300 | AF10: 305 | AG10: 0 | AH10: 305 | AI10: 6692 | AJ10: 33443.9 | AK10: 40135.9 | AL10: 10333.34 | AM10: 10333.34 | AN10: 0 | AO10: 300 | AP10: 305 | AS10: 468 | AT10: 424.49 | AU10: 305 | AV10: 300 | AW10: 468 | AX10: 400 | AY10: 305 | AZ10: 300
A11: 33079.67 | B11: -4300 | C11: 32663.43 | D11: 7487.01 | E11: 290 | F11: 7199 | G11: 415.49 | H11: 415.49 | I11: 580.14 | J11: 626.55 | K11: 568.13 | L11: 568.13 | M11: 899.1 | N11: 918.01 | O11: 365.7 | P11: 310.2 | Q11: 33029.86 | R11: 4265.891 | S11: 8039.125 | T11: 0.971 | U11: 8040.096 | V11: -545.1 | W11: 49.966 | X11: 12743.72 | Y11: 5315.141 | Z11: 1244.85 | AA11: 是 | AB11: -3048.747 | AC11: 290 | AD11: 0 | AE11: 290 | AF11: 313 | AG11: 0 | AH11: 313 | AI11: 6692 | AJ11: 33380 | AK11: 40072 | AL11: 10327.88 | AM11: 10327.88 | AN11: 0 | AO11: 290 | AP11: 313 | AS11: 468 | AT11: 361 | AU11: 313 | AV11: 290 | AW11: 468 | AX11: 301 | AY11: 313 | AZ11: 290
A12: 32703.65 | B12: -4301.2 | C12: 32565.52 | D12: 7628.87 | E12: 290 | F12: 7199 | G12: 388.14 | H12: 389.01 | I12: 579.23 | J12: 625.64 | K12: 561.85 | L12: 565.1 | M12: 899.1 | N12: 919.66 | O12: 361.2 | P12: 303.8 | Q12: 32863.72 | R12: 4357.412 | S12: 8629.98 | T12: 1.031 | U12: 8631.011 | V12: -568.95 | W12: 50.033 | X12: 13413.11 | Y12: 4588.332 | Z12: 1141.96 | AA12: 是 | AB12: -3072.56 | AC12: 290 | AD12: 0 | AE12: 290 | AF12: 310 | AG12: 0 | AH12: 310 | AI12: 6692 | AJ12: 33219.1 | AK12: 39911.1 | AL12: 10331.36 | AM12: 10331.36 | AN12: 0 | AO12: 290 | AP12: 310 | AS12: 468 | AT12: 361 | AU12: 310 | AV12: 290 | AW12: 468 | AX12: 301 | AY12: 310 | AZ12: 290
A13: 32837.81 | B13: -4117.18 | C13: 32670.72 | D13: 7923.78 | E13: 290 | F13: 7199 | G13: 422.34 | H13: 418.9 | I13: 579.31 | J13: 627.05 | K13: 571.61 | L13: 569.52 | M13: 899.1 | N13: 920.48 | O13: 364.5 | P13: 306 | Q13: 32602.91 | R13: 4334.71 | S13: 9218.598 | T13: 0.921 | U13: 9219.519 | V13: -1171.05 | W13: 50.004 | X13: 13669.79 | Y13: 4561.5 | Z13: 1143.6 | AA13: 是 | AB13: -3029.697 | AC13: 290 | AD13: 0 | AE13: 290 | AF13: 320 | AG13: 0 | AH13: 320 | AI13: 6692 | AJ13: 33287.4 | AK13: 39979.4 | AL13: 10344.65 | AM13: 10344.65 | AN13: 0 | AO13: 290 | AP13: 320 | AS13: 468 | AT13: 361 | AU13: 320 | AV13: 290 | AW13: 468 | AX13: 301 | AY13: 320 | AZ13: 290
A14: 32822.47 | B14: -4309.43 | C14: 31976.27 | D14: 8206.74 | E14: 282.2 | F14: 7199 | G14: 303.54 | H14: 306.97 | I14: 580.19 | J14: 626.86 | K14: 550.91 | L14: 553.01 | M14: 899.51 | N14: 919.66 | O14: 365.2 | P14: 306.7 | Q14: 32530.68 | R14: 4276.292 | S14: 9657.475 | T14: 1.021 | U14: 9658.496 | V14: -1171.66 | W14: 50.019 | X14: 14237.53 | Y14: 4046.777 | Z14: 1121.69 | AA14: 是 | AB14: -3059.813 | AC14: 282.2 | AD14: 0 | AE14: 282.2 | AF14: 310 | AG14: 0 | AH14: 310 | AI14: 6692 | AJ14: 33213.2 | AK14: 39905.2 | AL14: 10394.78 | AM14: 10394.78 | AN14: 0 | AO14: 282.2 | AP14: 310 | AS14: 468 | AT14: 361 | AU14: 310 | AV14: 282.2 | AW14: 468 | AX14: 301 | AY14: 310 | AZ14: 282.2
... A97: 33365.4 | B97: -6284.8 | C97: 29792.34 | D97: 12582.79 | E97: 270 | F97: 7199 | G97: 0 | H97: 248.86 | I97: 502.43 | J97: 536.72 | K97: 429.96 | L97: 432.52 | M97: 826.75 | N97: 825.92 | O97: 353.8 | P97: 302.1 | Q97: 32941.45 | R97: 6659.868 | S97: 13433.646 | T97: 1.13 | U97: 13434.775 | V97: 65.7 | W97: 50.036 | X97: 14813.57 | Y97: 2767.395 | Z97: 1130.96 | AA97: 是 | AB97: -4132.232 | AC97: 270 | AD97: 0 | AE97: 270 | AF97: 249 | AG97: 0 | AH97: 249 | AI97: 6594 | AJ97: 34203.6 | AK97: 40797.6 | AL97: 15258.83 | AM97: 15258.83 | AN97: 0 | AO97: 270 | AP97: 249 | AS97: 361 | AT97: 361 | AU97: 249 | AV97: 270 | AW97: 301 | AX97: 301 | AY97: 249 | AZ97: 270

Sheet 2024年12月25日
A1: 用电负荷(MW) | B1: 外送计划(MW) | C1: 火电总计划(MW) | D1: 新能源总计划(MW) | E1: 用户侧价格(元/MWh) | F1: 特高压雁淮直流外送-电力(MW) | G1: 塔山3# | H1: 塔山4# | I1: 王家岭电厂1#机 | J1: 王家岭电厂2#机 | K1: 神泉1# | L1: 神泉2# | M1: 神泉二期3号机 | N1: 神泉二期4号机 | O1: 紫荆电厂01# | P1: 紫荆电厂02# | Q1: 系统负荷实际值(MW) | R1: 外送实际值(MW) | S1: 风电实际值(MW) | T1: 光伏实际值(MW) | U1: 风光总加实际值(MW) | V1: 水电实际值(MW) | W1: 频率实际值(MW) | X1: 实际上旋备用(MW) | Y1: 实际下旋备用(MW) | Z1: 非市场化机组实际出力(MW) | AA1: 湖关三回线-是否越限 | AB1: 湖关三-潮流(MW) | AC1: 实时节点边际电价-电能量价格(元/MWh) | AD1: 实时节点边际电价-阻塞价格(元/MWh) | AE1: 实时节点边际电价-节点电价(元/MWh) | AF1: 日前节点边际电价-电能量价格(元/MWh) | AG1: 日前节点边际电价-阻塞价格(元/MWh) | AH1: 日前节点边际电价-节点电价(元/MWh) | AI1: 日前联络线电力值(MW) | AJ1: 省内负荷预测电力值(MW) | AK1: 总加电力值(MW) | AL1: 电力值(MW) | AM1: 风电(MW) | AN1: 光伏(MW) | AO1: 实时出清价格(元/MWh) | AP1: 日前出清价格(元/MWh) | AQ1: 日前-出清概况 | AR1: 实时-出清概况 | AS1: 1#日前结果(MW) | AT1: 1#实时结果(MW) | AU1: 1#日前价格(元/MWh) | AV1: 1#实时价格(元/MWh) | AW1: 2#日前结果(MW) | AX1: 2#实时结果(MW) | AY1: 2#日前价格(元/MWh) | AZ1: 2#实时价格(元/MWh)
A2: 34097.78 | B2: -5870.59 | C2: 29199.64 | D2: 13382.99 | E2: 250 | F2: 7199 | G2: 242.04 | H2: 240.32 | I2: 466.27 | J2: 469.56 | K2: 269 | L2: 271.56 | M2: 705.47 | N2: 702.59 | O2: 358.9 | P2: 305.4 | Q2: 33689.46 | R2: 6066.487 | S2: 13202.763 | T2: 0.165 | U2: 13202.928 | V2: 95.18 | W2: 49.967 | X2: 15944.16 | Y2: 3089.02 | Z2: 1090.92 | AA2: 是 | AB2: -4566.327 | AC2: 250 | AD2: 0 | AE2: 250 | AF2: 282.2 | AG2: 0 | AH2: 282.2 | AI2: 6692 | AJ2: 34942.7 | AK2: 41634.7 | AL2: 14310.23 | AM2: 14310.23 | AN2: 0 | AO2: 250 | AP2: 291.1 | AQ2: 12月25日,直调用电预测最大负荷4034.30万千瓦，最小3246.03万千瓦；外送电最大898.60万千瓦，最小585.75万千瓦；日前现货市场出清节点电价最大1500.00元/MWh，最小0.00元/MWh，算术平均190.71元/MWh；日前现货市场火电机组运行130台，运行机组容量46422.00MW；日前调频市场需求最大值4633.10MW，需求最小值为4214.87MW；中标机组最多25台，中标机组最少21台；中标机组调频性能指标平均值为3.67；边际出清价格最大30.00元/MWh，最小5.00元/MWh；火电机组必开97台次、必开容量30391.00MW，必停23台次、必停容量3093.00MW。 | AR2: 12月25日直调用电实际最大负荷3900.97万千瓦，最小3118.89万千瓦；12月25日日外送电实际安排最大898.60万千瓦，最小585.75万千瓦；12月25日实时现货市场出清价格最大330.00元/MWh，最小0.00元/MWh，算术平均130.60元/MWh；实时现货市场有阻塞，铺吉双断面负载率最高，达到100.00%;卧湖三回断面负载率次高，达到100.00%。 | AS2: 361 | AT2: 361 | AU2: 282.2 | AV2: 250 | AW2: 361 | AX2: 361 | AY2: 282.2 | AZ2: 250
A3: 33873.5 | B3: -5729.24 | C3: 27809.81 | D3: 13482.67 | E3: 18.57 | F3: 7199 | G3: 196.74 | H3: 199.3 | I3: 358.29 | J3: 348.97 | K3: 270.4 | L3: 271.1 | M3: 664.77 | N3: 663.95 | O3: 357.5 | P3: 302.2 | Q3: 34189.16 | R3: 5603.993 | S3: 13425.335 | T3: 0.168 | U3: 13425.502 | V3: 88.49 | W3: 50.033 | X3: 16122.61 | Y3: 2444.145 | Z3: 1099.14 | AA3: 是 | AB3: -4644.209 | AC3: 0 | AD3: 266.67 | AE3: 266.67 | AF3: 268 | AG3: 0 | AH3: 268 | AI3: 6692 | AJ3: 34843.4 | AK3: 41535.4 | AL3: 14406.13 | AM3: 14406.13 | AN3: 0 | AO3: 18.57 | AP3: 276.94 | AS3: 361 | AT3: 361 | AU3: 268 | AV3: 266.67 | AW3: 361 | AX3: 361 | AY3: 268 | AZ3: 266.67
A4: 33704.98 | B4: -5643.1 | C4: 27818.92 | D4: 13315.33 | E4: 110.88 | F4: 7199 | G4: 195.89 | H4: 195.89 | I4: 300.72 | J4: 329.41 | K4: 270.4 | L4: 272.26 | M4: 635.17 | N4: 638.05 | O4: 360.4 | P4: 305.1 | Q4: 34021.37 | R4: 5700.76 | S4: 13490.346 | T4: 0.222 | U4: 13490.568 | V4: 87.09 | W4: 50.025 | X4: 16261.99 | Y4: 2255.531 | Z4: 1141.11 | AA4: 是 | AB4: -4693.376 | AC4: 100 | AD4: 155.56 | AE4: 255.56 | AF4: 250 | AG4: 0 | AH4: 250 | AI4: 6692 | AJ4: 34744 | AK4: 41436 | AL4: 14491.29 | AM4: 14491.29 | AN4: 0 | AO4: 110.88 | AP4: 250 | AS4: 361 | AT4: 361 | AU4: 250 | AV4: 255.56 | AW4: 361 | AX4: 361 | AY4: 250 | AZ4: 255.56
A5: 33656.66 | B5: -5514.49 | C5: 27859.41 | D5: 13226.26 | E5: 110.91 | F5: 7199 | G5: 195.02 | H5: 195.89 | I5: 301.7 | J5: 331.05 | K5: 271.33 | L5: 271.56 | M5: 638.46 | N5: 638.87 | O5: 360.9 | P5: 305.6 | Q5: 33855.37 | R5: 5548.375 | S5: 13613.172 | T5: 0.194 | U5: 13613.366 | V5: 88.19 | W5: 50.011 | X5: 16705.19 | Y5: 1758.809 | Z5: 1121.77 | AA5: 是 | AB5: -4688.473 | AC5: 100 | AD5: 155.56 | AE5: 255.56 | AF5: 267 | AG5: 0 | AH5: 267 | AI5: 6692 | AJ5: 34495.7 | AK5: 41187.7 | AL5: 14573.67 | AM5: 14573.67 | AN5: 0 | AO5: 110.91 | AP5: 267 | AS5: 361 | AT5: 361 | AU5: 267 | AV5: 255.56 | AW5: 361 | AX5: 361 | AY5: 267 | AZ5: 255.56
A6: 33544.49 | B6: -5767.13 | C6: 27846.01 | D6: 13301.24 | E6: 110.91 | F6: 7199 | G6: 194.17 | H6: 195.89 | I6: 297.6 | J6: 329.77 | K6: 271.1 | L6: 272.49 | M6: 638.46 | N6: 637.22 | O6: 358.7 | P6: 303.8 | Q6: 33187.05 | R6: 5710.38 | S6: 13607.398 | T6: 0.158 | U6: 13607.556 | V6: 67.79 | W6: 50.034 | X6: 17202.57 | Y6: 1318.445 | Z6: 1131.04 | AA6: 是 | AB6: -4693.236 | AC6: 100 | AD6: 155.56 | AE6: 255.56 | AF6: 255 | AG6: 0 | AH6: 255 | AI6: 6692 | AJ6: 34172.8 | AK6: 40864.8 | AL6: 14657.35 | AM6: 14657.35 | AN6: 0 | AO6: 110.91 | AP6: 255 | AS6: 361 | AT6: 361 | AU6: 255 | AV6: 255.56 | AW6: 361 | AX6: 361 | AY6: 255 | AZ6: 255.56
A7: 33169.91 | B7: -5968.29 | C7: 27611.53 | D7: 13301.73 | E7: 18.88 | F7: 7199 | G7: 195.89 | H7: 195.89 | I7: 300.34 | J7: 330.39 | K7: 271.1 | L7: 271.56 | M7: 638.05 | N7: 637.64 | O7: 362.6 | P7: 304.8 | Q7: 33222.76 | R7: 5925.754 | S7: 13723.341 | T7: 0.21 | U7: 13723.551 | V7: 66.54 | W7: 49.978 | X7: 17070.63 | Y7: 1568.648 | Z7: 1137.13 | AA7: 是 | AB7: -4685.812 | AC7: 0 | AD7: 266.67 | AE7: 266.67 | AF7: 250 | AG7: 0 | AH7: 250 | AI7: 6692 | AJ7: 33999 | AK7: 40691 | AL7: 14737.86 | AM7: 14737.86 | AN7: 0 | AO7: 18.88 | AP7: 250 | AS7: 361 | AT7: 361 | AU7: 250 | AV7: 266.67 | AW7: 361 | AX7: 361 | AY7: 250 | AZ7: 266.67
A8: 32968.36 | B8: -6006.16 | C8: 27636.26 | D8: 12806.59 | E8: 18.96 | F8: 7199 | G8: 194.17 | H8: 195.89 | I8: 299.8 | J8: 329.88 | K8: 271.1 | L8: 271.56 | M8: 638.05 | N8: 638.05 | O8: 359.9 | P8: 304.2 | Q8: 33025.86 | R8: 5947.187 | S8: 13652.249 | T8: 0.127 | U8: 13652.376 | V8: 67.84 | W8: 50.033 | X8: 17176.62 | Y8: 1470.141 | Z8: 1124.01 | AA8: 是 | AB8: -4696.317 | AC8: 0 | AD8: 266.67 | AE8: 266.67 | AF8: 200 | AG8: 44.44 | AH8: 244.44 | AI8: 6692 | AJ8: 33825.2 | AK8: 40517.2 | AL8: 14822 | AM8: 14822 | AN8: 0 | AO8: 18.96 | AP8: 203.08 | AS8: 361 | AT8: 361 | AU8: 244.44 | AV8: 266.67 | AW8: 361 | AX8: 361 | AY8: 244.44 | AZ8: 266.67
A9: 32988.04 | B9: -5745.98 | C9: 27639.73 | D9: 12603.16 | E9: 18.99 | F9: 7199 | G9: 195.02 | H9: 196.74 | I9: 300.22 | J9: 331.07 | K9: 270.16 | L9: 271.1 | M9: 638.05 | N9: 637.22 | O9: 360.1 | P9: 305.7 | Q9: 32735.46 | R9: 5895.786 | S9: 13504.546 | T9: 0.118 | U9: 13504.664 | V9: 61.04 | W9: 49.969 | X9: 17362.51 | Y9: 1285.27 | Z9: 1135.74 | AA9: 是 | AB9: -4692.255 | AC9: 0 | AD9: 266.67 | AE9: 266.67 | AF9: 250 | AG9: 0 | AH9: 250 | AI9: 6692 | AJ9: 33750.7 | AK9: 40442.7 | AL9: 14900.56 | AM9: 14900.56 | AN9: 0 | AO9: 18.99 | AP9: 250 | AS9: 361 | AT9: 361 | AU9: 250 | AV9: 266.67 | AW9: 361 | AX9: 361 | AY9: 250 | AZ9: 266.67
A10: 32837.07 | B10: -5048.08 | C10: 27239.27 | D10: 12476.27 | E10: 19.28 | F10: 7199 | G10: 194.17 | H10: 195.89 | I10: 300.74 | J10: 330.45 | K10: 271.1 | L10: 271.79 | M10: 637.64 | N10: 636.81 | O10: 357.5 | P10: 301.9 | Q10: 32855.62 | R10: 5204.788 | S10: 13540.27 | T10: 0.138 | U10: 13540.408 | V10: -250.66 | W10: 50.03 | X10: 17655.02 | Y10: 1012.141 | Z10: 1152.42 | AA10: 是 | AB10: -4700.52 | AC10: 0 | AD10: 266.67 | AE10: 266.67 | AF10: 250 | AG10: 0 | AH10: 250 | AI10: 6692 | AJ10: 33651.3 | AK10: 40343.3 | AL10: 14977.68 | AM10: 14977.68 | AN10: 0 | AO10: 19.28 | AP10: 250 | AS10: 361 | AT10: 361 | AU10: 250 | AV10: 266.67 | AW10: 361 | AX10: 361 | AY10: 250 | AZ10: 266.67
A11: 32596.87 | B11: -5135.66 | C11: 27389.62 | D11: 12478.88 | E11: 19.25 | F11: 7199 | G11: 195.02 | H11: 195.89 | I11: 300.18 | J11: 330.33 | K11: 270.4 | L11: 270.86 | M11: 637.64 | N11: 637.22 | O11: 361.2 | P11: 305.1 | Q11: 32653.9 | R11: 5083.181 | S11: 13536.536 | T11: 0.142 | U11: 13536.679 | V11: -555.66 | W11: 49.986 | X11: 17668.95 | Y11: 973.922 | Z11: 1134.95 | AA11: 是 | AB11: -4679.509 | AC11: 0 | AD11: 266.67 | AE11: 266.67 | AF11: 250 | AG11: 0 | AH11: 250 | AI11: 6692 | AJ11: 33552 | AK11: 40244 | AL11: 15046.11 | AM11: 15046.11 | AN11: 0 | AO11: 19.25 | AP11: 250 | AS11: 361 | AT11: 361 | AU11: 250 | AV11: 266.67 | AW11: 361 | AX11: 361 | AY11: 250 | AZ11: 266.67
A12: 32551.41 | B12: -5037 | C12: 27213.63 | D12: 12576.89 | E12: 19.44 | F12: 7197 | G12: 195.89 | H12: 195.89 | I12: 300.18 | J12: 330.63 | K12: 270.4 | L12: 271.1 | M12: 637.64 | N12: 636.81 | O12: 361.1 | P12: 300.8 | Q12: 32448.88 | R12: 5070.443 | S12: 13668.387 | T12: 0.139 | U12: 13668.526 | V12: -1172.66 | W12: 50.01 | X12: 17402.39 | Y12: 1435.832 | Z12: 1149.86 | AA12: 是 | AB12: -4690.995 | AC12: 0 | AD12: 266.67 | AE12: 266.67 | AF12: 260 | AG12: 0 | AH12: 260 | AI12: 6692 | AJ12: 33452.7 | AK12: 40144.7 | AL12: 15117.83 | AM12: 15117.83 | AN12: 0 | AO12: 19.44 | AP12: 260 | AS12: 361 | AT12: 361 | AU12: 260 | AV12: 266.67 | AW12: 361 | AX12: 361 | AY12: 260 | AZ12: 266.67
A13: 32343.85 | B13: -5092.14 | C13: 27354.75 | D13: 12869.38 | E13: 19.59 | F13: 7197 | G13: 195.02 | H13: 195.89 | I13: 299.98 | J13: 330.91 | K13: 270.86 | L13: 272.26 | M13: 637.22 | N13: 637.22 | O13: 363.2 | P13: 303.8 | Q13: 32514.06 | R13: 5117.498 | S13: 13872.877 | T13: 0.151 | U13: 13873.029 | V13: -1165.01 | W13: 49.985 | X13: 17494.4 | Y13: 1410.625 | Z13: 1143.09 | AA13: 是 | AB13: -4691.275 | AC13: 0 | AD13: 266.67 | AE13: 266.67 | AF13: 250 | AG13: 0 | AH13: 250 | AI13: 6692 | AJ13: 33353.3 | AK13: 40045.3 | AL13: 15183.14 | AM13: 15183.14 | AN13: 0 | AO13: 19.59 | AP13: 250 | AS13: 361 | AT13: 361 | AU13: 250 | AV13: 266.67 | AW13: 361 | AX13: 361 | AY13: 250 | AZ13: 266.67
A14: 32254.19 | B14: -5265.5 | C14: 27103.94 | D14: 13590.27 | E14: 19.78 | F14: 7197 | G14: 195.89 | H14: 195.89 | I14: 300.59 | J14: 329.77 | K14: 271.1 | L14: 271.1 | M14: 637.64 | N14: 637.22 | O14: 363.5 | P14: 304.1 | Q14: 32629.36 | R14: 5229.835 | S14: 13945.943 | T14: 0.197 | U14: 13946.14 | V14: -1165.61 | W14: 50.028 | X14: 17348.1 | Y14: 1426.172 | Z14: 1142.05 | AA14: 是 | AB14: -4714.947 | AC14: 0 | AD14: 266.67 | AE14: 266.67 | AF14: 250 | AG14: 0 | AH14: 250 | AI14: 6692 | AJ14: 33254 | AK14: 39946 | AL14: 15255.4 | AM14: 15255.4 | AN14: 0 | AO14: 19.78 | AP14: 250 | AS14: 361 | AT14: 361 | AU14: 250 | AV14: 266.67 | AW14: 361 | AX14: 361 | AY14: 250 | AZ14: 266.67
... A97: 33631.73 | B97: -5471.09 | C97: 32724.71 | D97: 9432.43 | E97: 313 | F97: 7199 | G97: 548.8 | H97: 541.11 | I97: 425.73 | J97: 537.67 | K97: 392.28 | L97: 379.25 | M97: 899.1 | N97: 919.25 | O97: 437.9 | P97: 392.2 | Q97: 33635.78 | R97: 5581.238 | S97: 8922.371 | T97: 1.106 | U97: 8923.476 | V97: 50.35 | W97: 50.033 | X97: 12298.73 | Y97: 7576.395 | Z97: 1115.63 | AA97: 是 | AB97: -3772.519 | AC97: 313 | AD97: 0 | AE97: 313 | AF97: 310 | AG97: 0 | AH97: 310 | AI97: 6594 | AJ97: 33981 | AK97: 40575 | AL97: 10891.42 | AM97: 10891.42 | AN97: 0 | AO97: 313 | AP97: 310 | AS97: 450 | AT97: 450 | AU97: 310 | AV97: 313 | AW97: 450 | AX97: 450 | AY97: 310 | AZ97: 313

Sheet 2024年12月24日
A1: 用电负荷(MW) | B1: 外送计划(MW) | C1: 火电总计划(MW) | D1: 新能源总计划(MW) | E1: 用户侧价格(元/MWh) | F1: 特高压雁淮直流外送-电力(MW) | G1: 塔山3# | H1: 塔山4# | I1: 王家岭电厂1#机 | J1: 王家岭电厂2#机 | K1: 神泉1# | L1: 神泉2# | M1: 神泉二期3号机 | N1: 神泉二期4号机 | O1: 紫荆电厂01# | P1: 紫荆电厂02# | Q1: 系统负荷实际值(MW) | R1: 外送实际值(MW) | S1: 风电实际值(MW) | T1: 光伏实际值(MW) | U1: 风光总加实际值(MW) | V1: 水电实际值(MW) | W1: 频率实际值(MW) | X1: 实际上旋备用(MW) | Y1: 实际下旋备用(MW) | Z1: 非市场化机组实际出力(MW) | AA1: 湖关三回线-是否越限 | AB1: 湖关三-潮流(MW) | AC1: 实时节点边际电价-电能量价格(元/MWh) | AD1: 实时节点边际电价-阻塞价格(元/MWh) | AE1: 实时节点边际电价-节点电价(元/MWh) | AF1: 日前节点边际电价-电能量价格(元/MWh) | AG1: 日前节点边际电价-阻塞价格(元/MWh) | AH1: 日前节点边际电价-节点电价(元/MWh) | AI1: 日前联络线电力值(MW) | AJ1: 省内负荷预测电力值(MW) | AK1: 总加电力值(MW) | AL1: 电力值(MW) | AM1: 风电(MW) | AN1: 光伏(MW) | AO1: 实时出清价格(元/MWh) | AP1: 日前出清价格(元/MWh) | AQ1: 日前-出清概况 | AR1: 实时-出清概况 | AS1: 1#日前结果(MW) | AT1: 1#实时结果(MW) | AU1: 1#日前价格(元/MWh) | AV1: 1#实时价格(元/MWh) | AW1: 2#日前结果(MW) | AX1: 2#实时结果(MW) | AY1: 2#日前价格(元/MWh) | AZ1: 2#实时价格(元/MWh)
A2: 35126.29 | B2: -6692 | C2: 44874.62 | D2: 2636.77 | E2: 398 | F2: 7197 | G2: 661.6 | H2: 662.44 | I2: 580.03 | J2: 649.03 | K2: 569.52 | L2: 572.54 | M2: 899.51 | N2: 919.66 | O2: 549.9 | P2: 550.8 | Q2: 35058.67 | R2: 6827.37 | S2: 2830.466 | T2: 0.934 | U2: 2831.4 | V2: 45.17 | W2: 49.966 | X2: 6095.211 | Y2: 15069.63 | Z2: 1169.71 | AA2: 是 | AB2: -3139.937 | AC2: 398 | AD2: 0 | AE2: 398 | AF2: 398.4 | AG2: 0 | AH2: 398.4 | AI2: 6692 | AJ2: 34975 | AK2: 41667 | AL2: 2262.68 | AM2: 2262.68 | AN2: 0 | AO2: 398 | AP2: 398.4 | AQ2: 12月24日,直调用电预测最大负荷4029.50万千瓦，最小3279.87万千瓦；外送电最大898.50万千瓦，最小585.75万千瓦；日前现货市场出清节点电价最大398.40元/MWh，最小0.00元/MWh，算术平均269.98元/MWh；日前现货市场火电机组运行134台，运行机组容量47502.00MW；日前调频市场需求最大值4628.30MW，需求最小值为4166.70MW；中标机组最多25台，中标机组最少21台；中标机组调频性能指标平均值为3.84；边际出清价格最大22.01元/MWh，最小5.00元/MWh；火电机组必开98台次、必开容量30491.00MW，必停23台次、必停容量3093.00MW。 | AR2: 12月24日直调用电实际最大负荷3959.78万千瓦，最小3169.74万千瓦；12月24日日外送电实际安排最大898.50万千瓦，最小585.75万千瓦；12月24日实时现货市场出清价格最大398.40元/MWh，最小0.00元/MWh，算术平均312.83元/MWh；实时现货市场有阻塞，铺吉双断面负载率最高，达到100.00%;湖关三回线断面负载率次高，达到100.00%。 | AS2: 606.7 | AT2: 550 | AU2: 398.4 | AV2: 398 | AW2: 606.7 | AX2: 550 | AY2: 398.4 | AZ2: 398
A3: 35224.34 | B3: -6692 | C3: 44579.9 | D3: 2758.14 | E3: 398.4 | F3: 7197 | G3: 660.73 | H3: 660.73 | I3: 581.13 | J3: 649.13 | K3: 570.22 | L3: 572.54 | M3: 898.69 | N3: 920.07 | O3: 574 | P3: 588 | Q3: 35038.23 | R3: 6682.976 | S3: 3133.257 | T3: 0.966 | U3: 3134.223 | V3: 45.03 | W3: 49.969 | X3: 5608.746 | Y3: 14924.68 | Z3: 1161.5 | AA3: 是 | AB3: -3089.509 | AC3: 398.4 | AD3: 0 | AE3: 398.4 | AF3: 398 | AG3: 0 | AH3: 398 | AI3: 6692 | AJ3: 34870 | AK3: 41562 | AL3: 2412 | AM3: 2412 | AN3: 0 | AO3: 398.4 | AP3: 398 | AS3: 550 | AT3: 581.73 | AU3: 398 | AV3: 398.4 | AW3: 550 | AX3: 581.73 | AY3: 398 | AZ3: 398.4
A4: 34858.66 | B4: -6692 | C4: 43891.82 | D4: 3018.32 | E4: 398.4 | F4: 7197 | G4: 661.6 | H4: 660.73 | I4: 580.84 | J4: 648.95 | K4: 569.29 | L4: 573.94 | M4: 898.69 | N4: 920.48 | O4: 555.2 | P4: 556.4 | Q4: 34843.71 | R4: 6972.621 | S4: 3584.358 | T4: 1.029 | U4: 3585.387 | V4: 45.08 | W4: 49.966 | X4: 5961.242 | Y4: 14798.6 | Z4: 1113.83 | AA4: 是 | AB4: -3142.458 | AC4: 398.4 | AD4: 0 | AE4: 398.4 | AF4: 395.8 | AG4: 0 | AH4: 395.8 | AI4: 6692 | AJ4: 34623 | AK4: 41315 | AL4: 2568.93 | AM4: 2568.93 | AN4: 0 | AO4: 398.4 | AP4: 395.8 | AS4: 550 | AT4: 555.6 | AU4: 395.8 | AV4: 398.4 | AW4: 550 | AX4: 555.6 | AY4: 395.8 | AZ4: 398.4
A5: 34779.93 | B5: -6692 | C5: 43512.91 | D5: 3248.72 | E5: 398.4 | F5: 7195 | G5: 661.6 | H5: 661.6 | I5: 581.69 | J5: 648.84 | K5: 570.68 | L5: 572.54 | M5: 898.28 | N5: 919.66 | O5: 555.2 | P5: 555.3 | Q5: 34767.75 | R5: 6769.814 | S5: 3946.524 | T5: 0.987 | U5: 3947.511 | V5: 45.13 | W5: 50.014 | X5: 6596.809 | Y5: 14192.36 | Z5: 1105.34 | AA5: 是 | AB5: -3142.458 | AC5: 398.4 | AD5: 0 | AE5: 398.4 | AF5: 389 | AG5: 0 | AH5: 389 | AI5: 6692 | AJ5: 34371 | AK5: 41063 | AL5: 2732.1 | AM5: 2732.1 | AN5: 0 | AO5: 398.4 | AP5: 389 | AS5: 550 | AT5: 556.07 | AU5: 389 | AV5: 398.4 | AW5: 550 | AX5: 556.07 | AY5: 389 | AZ5: 398.4
A6: 34483.35 | B6: -6692 | C6: 41617.62 | D6: 3465.71 | E6: 370 | F6: 7199 | G6: 660.73 | H6: 660.73 | I6: 581.11 | J6: 639.78 | K6: 569.99 | L6: 573.24 | M6: 898.69 | N6: 919.66 | O6: 535.8 | P6: 536 | Q6: 34468.61 | R6: 6592.229 | S6: 4092.355 | T6: 0.941 | U6: 4093.297 | V6: 45.27 | W6: 50.011 | X6: 7210.039 | Y6: 13519.19 | Z6: 1113.51 | AA6: 是 | AB6: -3185.601 | AC6: 370 | AD6: 0 | AE6: 370 | AF6: 390 | AG6: 0 | AH6: 390 | AI6: 6692 | AJ6: 34213 | AK6: 40905 | AL6: 2868.04 | AM6: 2868.04 | AN6: 0 | AO6: 370 | AP6: 390 | AS6: 550 | AT6: 536.88 | AU6: 390 | AV6: 370 | AW6: 550 | AX6: 536.88 | AY6: 390 | AZ6: 370
A7: 34171.78 | B7: -6692 | C7: 40883.01 | D7: 3727.35 | E7: 370 | F7: 7199 | G7: 653.03 | H7: 655.6 | I7: 581.66 | J7: 644.83 | K7: 569.06 | L7: 572.78 | M7: 898.69 | N7: 918.84 | O7: 478.3 | P7: 478.6 | Q7: 34120.48 | R7: 6666.062 | S7: 4195.187 | T7: 0.97 | U7: 4196.158 | V7: 45.22 | W7: 49.973 | X7: 7590.449 | Y7: 13167.21 | Z7: 1130.71 | AA7: 是 | AB7: -3285.055 | AC7: 370 | AD7: 0 | AE7: 370 | AF7: 380 | AG7: 0 | AH7: 380 | AI7: 6692 | AJ7: 34057 | AK7: 40749 | AL7: 3030.05 | AM7: 3030.05 | AN7: 0 | AO7: 370 | AP7: 380 | AS7: 550 | AT7: 480.03 | AU7: 380 | AV7: 370 | AW7: 550 | AX7: 480.03 | AY7: 380 | AZ7: 370
A8: 33962.81 | B8: -6692 | C8: 40495.08 | D8: 3961.96 | E8: 360 | F8: 7199 | G8: 651.34 | H8: 652.19 | I8: 580.8 | J8: 644.84 | K8: 570.22 | L8: 572.54 | M8: 899.1 | N8: 919.66 | O8: 467.2 | P8: 467.3 | Q8: 34102.5 | R8: 6673.027 | S8: 4225.036 | T8: 0.963 | U8: 4225.998 | V8: 45.17 | W8: 50.003 | X8: 7618.48 | Y8: 13132.54 | Z8: 1138.14 | AA8: 是 | AB8: -3316.572 | AC8: 360 | AD8: 0 | AE8: 360 | AF8: 372.64 | AG8: 0 | AH8: 372.64 | AI8: 6692 | AJ8: 33919 | AK8: 40611 | AL8: 3148.49 | AM8: 3148.49 | AN8: 0 | AO8: 360 | AP8: 372.64 | AS8: 550 | AT8: 468 | AU8: 372.64 | AV8: 360 | AW8: 550 | AX8: 468 | AY8: 372.64 | AZ8: 360
